<?xml version='1.0' encoding='UTF-8'?>
<!-- Cassie simulation model developed by the Dynamic Robotics Laboratory -->
<mujoco model="cassie">
  <compiler inertiafromgeom="auto" angle="degree" eulerseq="zyx" meshdir="cassie-stl-meshes"/>
  <size nuser_actuator="1" nuser_sensor="1" nuser_geom="1"/>
  <option timestep="0.0005" iterations="50" solver="PGS" gravity="0 0 -9.81"/>
  <!-- Timestep is set to 0.0005 because our controller runs at 2 kHz -->
  <!-- Larger values still have stable dynamics -->
  <visual>
    <quality shadowsize="4096"/>
    <map znear="0.05"/>
  </visual>
  <default>
    <joint limited="true"/>
    <motor ctrllimited="true"/>
    <!-- <geom contype='0' conaffinity='0' condim='1' solref='0.005 1' friction='.4 0.0001 0.00001'/> -->
    <geom contype="0" conaffinity="0" condim="1" solref="0.005 1"/>
    <equality solref="0.005 1"/>
    <default class="cassie">
      <geom material="cassie"/>
    </default>
    <default class="collision">
      <!-- User parameter for geoms is used to identify collision types -->
      <geom material="collision" contype="1" user="2"/>
      <default class="collision-left">
        <geom contype="2" conaffinity="4"/>
      </default>
      <default class="collision-right">
        <geom contype="4" conaffinity="2"/>
      </default>
    </default>
    <default class="obstacle">
      <geom material="obstacle" condim="3" contype="8" conaffinity="15" user="1"/>
    </default>
  </default>
  <asset>
    <texture type="skybox" builtin="gradient" width="128" height="128" rgb1="0.4 0.6 0.8" rgb2="0 0 0"/>
    <texture name="plane" type="2d" builtin="checker" rgb1="0.2 0.2 0.2" rgb2="0.3 0.3 0.3" width="512" height="512"/>
    <material name="plane" reflectance="0.0" texture="plane" texrepeat="1 1" texuniform="true"/>
    <material name="cassie" rgba="0.9 0.5 0.1 1"/>
    <material name="collision" rgba="0.1 0.5 0.9 0"/>
    <material name="obstacle" rgba="0.2 0.6 0.2 1"/>
    <mesh name="cassie-pelvis" file="pelvis.stl"/>
    <mesh name="left-hip-roll" file="hip-roll.stl"/>
    <mesh name="left-hip-yaw" file="hip-yaw.stl"/>
    <mesh name="left-hip-pitch" file="hip-pitch.stl"/>
    <mesh name="left-achilles-rod" file="achilles-rod.stl"/>
    <mesh name="left-knee" file="knee.stl"/>
    <mesh name="left-knee-spring" file="knee-spring.stl"/>
    <mesh name="left-shin" file="shin.stl"/>
    <mesh name="left-tarsus" file="tarsus.stl"/>
    <mesh name="left-heel-spring" file="heel-spring.stl"/>
    <mesh name="left-foot-crank" file="foot-crank.stl"/>
    <mesh name="left-plantar-rod" file="plantar-rod.stl"/>
    <mesh name="left-foot" file="foot.stl"/>
    <mesh name="right-hip-roll" scale="1 -1 1" file="hip-roll.stl"/>
    <mesh name="right-hip-yaw" scale="1 -1 1" file="hip-yaw.stl"/>
    <mesh name="right-hip-pitch" scale="1 1 -1" file="hip-pitch.stl"/>
    <mesh name="right-achilles-rod" scale="1 1 -1" file="achilles-rod.stl"/>
    <mesh name="right-knee" scale="1 1 -1" file="knee.stl"/>
    <mesh name="right-knee-spring" scale="1 1 -1" file="knee-spring.stl"/>
    <mesh name="right-shin" scale="1 1 -1" file="shin.stl"/>
    <mesh name="right-tarsus" scale="1 1 -1" file="tarsus.stl"/>
    <mesh name="right-heel-spring" scale="1 1 -1" file="heel-spring.stl"/>
    <mesh name="right-foot-crank" scale="1 1 -1" file="foot-crank.stl"/>
    <mesh name="right-plantar-rod" scale="1 1 -1" file="plantar-rod.stl"/>
    <mesh name="right-foot" scale="1 1 -1" file="foot.stl"/>
  </asset>
  <worldbody>
    <geom name="floor" pos="0 0 -0.01" size="100 5 .125" type="plane" material="plane" condim="3" conaffinity="15" priority="1"/>
    <light mode="trackcom" pos="0 0 5" dir="0 0 -1"/>
    <light directional="true" pos="0 0 3" dir="0 0 -1" diffuse="0.2 0.2 0.2" specular="0 0 0"/>
    <body name="cassie-pelvis" pos="0 0 1.01" childclass="cassie">
      <camera name="track" pos="0 -3 1" zaxis="0 -1 0.5" mode="track"/>
      <!--camera name='track' pos='-3 0 0' xyaxes='0 -1 0 0 0 1' mode='track'/-->
      <inertial pos="0.05066 0.000346 0.02841" mass="10.33" fullinertia="0.085821 0.049222 0.08626 1.276e-05 -0.00016022 -0.000414"/>
      <joint type="slide" axis="1 0 0" limited="false"/>
      <joint type="slide" axis="0 1 0" limited="false"/>
      <joint type="slide" axis="0 0 1" limited="false" ref="1.01"/>
      <joint type="ball" limited="false"/>
      <geom type="mesh" mesh="cassie-pelvis"/>
      <geom type="sphere" size="0.15" pos="0.02 0 0.02" class="collision"/>
      <site name="imu" size="0.01" pos="0.03155 0 -0.07996"/>
      <body name="left-hip-roll" pos="0.021 0.135 0" xyaxes="0 0 -1 0 1 0">
        <inertial pos="-0.01793 0.0001 -0.04428" mass="1.82" fullinertia="0.003431 0.003793 0.002135 -6.65e-07 -0.00084 3.99e-06"/>
        <joint name="left-hip-roll" type="hinge" range="-15 22.5" damping="1" armature="0.038125"/>
        <geom type="mesh" mesh="left-hip-roll"/>
        <body name="left-hip-yaw" pos="0 0 -0.07" xyaxes="0 0 1 0 1 0">
          <inertial pos="0 -1e-05 -0.034277" mass="1.171" fullinertia="0.002443 0.002803 0.000842 -4e-08 2.462e-07 -2.71e-08"/>
          <joint name="left-hip-yaw" type="hinge" range="-22.5 22.5" damping="1" armature="0.038125"/>
          <geom type="mesh" mesh="left-hip-yaw"/>
          <body name="left-hip-pitch" pos="0 0 -0.09" xyaxes="0 0 -1 1 0 0">
            <inertial pos="0.05946 5e-05 -0.03581" mass="5.52" fullinertia="0.010898 0.029714 0.030257 -0.0002669 -5.721e-05 9.17e-06"/>
            <joint name="left-hip-pitch" type="hinge" range="-50 80" damping="1" armature="0.09344"/>
            <geom type="mesh" mesh="left-hip-pitch"/>
            <geom type="capsule" size="0.08" fromto="0 0 -0.04 0.12 0 -0.0355" class="collision"/>
            <body name="left-achilles-rod" pos="0 0 0.045" xyaxes="0.7922 -0.60599 -0.072096 0.60349 0.79547 -0.054922">
              <inertial pos="0.24719 0 0" mass="0.1567" fullinertia="3.754e-06 0.004487 0.004488 -3.74e-08 -1.61e-08 0"/>
              <joint name="left-achilles-rod" type="ball" limited="false" damping="0.01"/>
              <geom type="mesh" mesh="left-achilles-rod"/>
            </body>
            <body name="left-knee" pos="0.12 0 0.0045" xyaxes="0.70711 -0.70711 0 0.70711 0.70711 0">
              <inertial pos="0.023 0.03207 -0.002181" mass="0.7578" fullinertia="0.001376 0.0010335 0.0021637 -0.00039744 -4.085e-05 -5.374e-05"/>
              <joint name="left-knee" type="hinge" ref="-45" range="-164 -37" damping="1" armature="0.09344"/>
              <geom type="mesh" mesh="left-knee"/>
              <body name="left-knee-spring" pos="0.06068 0.08241 0">
                <inertial pos="0.0836 0.0034 0" mass="0.186" fullinertia="5.215e-05 0.00041205 0.0003669 6.87e-06 0 0"/>
                <geom type="mesh" mesh="left-knee-spring"/>
              </body>
              <body name="left-shin" pos="0.06068 0.04741 0">
                <inertial pos="0.18338 0.001169 0.0002123" mass="0.577" fullinertia="0.00035939 0.014728 0.014707 -0.00020981 2.266e-05 -1.2e-07"/>
                <joint name="left-shin" type="hinge" range="-20 20" stiffness="1500" damping="0.1"/>
                <geom type="mesh" mesh="left-shin"/>
                <geom type="capsule" size="0.04" fromto="0 0 0 0.43476 0.02 0" class="collision-left"/>
                <body name="left-tarsus" pos="0.43476 0.02 0" xyaxes="0.52992 0.84805 0 -0.84805 0.52992 0">
                  <inertial pos="0.11046 -0.03058 -0.00131" mass="0.782" fullinertia="0.00039238 0.013595 0.013674 0.00023651 -4.987e-05 -4.82e-06"/>
                  <joint name="left-tarsus" type="hinge" ref="58" range="50 170" damping="0.1"/>
                  <geom type="mesh" mesh="left-tarsus"/>
                  <geom type="capsule" size="0.04" fromto="-0.01269 -0.03059 0.00092 0.408 -0.04 0" class="collision-left"/>
                  <body name="left-heel-spring" pos="-0.01269 -0.03059 0.00092" xyaxes="-0.91211 0.40829 0.036948 -0.40992 -0.90952 -0.068841">
                    <inertial pos="0.081 0.0022 0" mass="0.126" fullinertia="2.959e-05 0.00022231 0.0002007 7.15e-06 -6e-07 1e-07"/>
                    <joint name="left-heel-spring" type="hinge" limited="false" stiffness="1250"/>
                    <geom type="mesh" mesh="left-heel-spring"/>
                  </body>
                  <body name="left-foot-crank" pos="0.058 -0.034 0.02275">
                    <inertial pos="0.00493 2e-05 -0.00215" mass="0.1261" fullinertia="2.6941e-05 4.9621e-05 6.3362e-05 -2.1e-09 -3.9623e-06 -1.09e-08"/>
                    <joint name="left-foot-crank" type="hinge" range="-140 -30" damping="1"/>
                    <geom type="mesh" mesh="left-foot-crank"/>
                    <body name="left-plantar-rod" pos="0.055 0 -0.00791">
                      <inertial pos="0.17792 0 0" mass="0.1186" fullinertia="2.779e-06 0.001774 0.001775 -2.34e-08 -8.1e-09 0"/>
                      <joint name="left-plantar-rod" type="hinge" limited="false"/>
                      <geom type="mesh" mesh="left-plantar-rod"/>
                    </body>
                  </body>
                  <body name="left-foot" pos="0.408 -0.04 0">
                    <inertial pos="0.00474 0.02748 -0.00014" mass="0.1498" fullinertia="0.00017388 0.00016793 0.00033261 0.00011814 1.36e-06 -4e-07"/>
                    <joint name="left-foot" type="hinge" range="-140 -30" damping="1" armature="0.01225"/>
                    <geom type="mesh" mesh="left-foot"/>
                    <geom type="capsule" size="0.02" fromto="-0.052821 0.092622 0 0.069746 -0.010224 0" class="collision-left"/>
                  </body>
                </body>
              </body>
            </body>
          </body>
        </body>
      </body>
      <body name="right-hip-roll" pos="0.021 -0.135 0" xyaxes="0 0 -1 0 1 0">
        <inertial pos="-0.01793 0.0001 -0.04428" mass="1.82" fullinertia="0.003431 0.003793 0.002135 6.65e-07 -0.00084 -3.99e-06"/>
        <joint name="right-hip-roll" type="hinge" range="-22.5 15" damping="1" armature="0.038125"/>
        <geom type="mesh" mesh="right-hip-roll"/>
        <body name="right-hip-yaw" pos="0 0 -0.07" xyaxes="0 0 1 0 1 0">
          <inertial pos="0 1e-05 -0.034277" mass="1.171" fullinertia="0.002443 0.002803 0.000842 4e-08 2.462e-07 2.71e-08"/>
          <joint name="right-hip-yaw" type="hinge" range="-22.5 22.5" damping="1" armature="0.038125"/>
          <geom type="mesh" mesh="right-hip-yaw"/>
          <body name="right-hip-pitch" pos="0 0 -0.09" xyaxes="0 0 -1 1 0 0">
            <inertial pos="0.05946 5e-05 0.03581" mass="5.52" fullinertia="0.010898 0.029714 0.030257 -0.0002669 5.721e-05 -9.17e-06"/>
            <joint name="right-hip-pitch" type="hinge" range="-50 80" damping="1" armature="0.09344"/>
            <geom type="mesh" mesh="right-hip-pitch"/>
            <geom type="capsule" size="0.08" fromto="0 0 0.04 0.12 0 0.0355" class="collision"/>
            <body name="right-achilles-rod" pos="0 0 -0.045" xyaxes="0.7922 -0.60599 0.072096 0.60349 0.79547 0.054922">
              <inertial pos="0.24719 0 0" mass="0.1567" fullinertia="3.754e-06 0.004487 0.004488 -3.74e-08 1.61e-08 0"/>
              <joint name="right-achilles-rod" type="ball" limited="false" damping="0.01"/>
              <geom type="mesh" mesh="right-achilles-rod"/>
            </body>
            <body name="right-knee" pos="0.12 0 -0.0045" xyaxes="0.70711 -0.70711 0 0.70711 0.70711 0">
              <inertial pos="0.023 0.03207 0.002181" mass="0.7578" fullinertia="0.001376 0.0010335 0.0021637 -0.00039744 4.085e-05 5.374e-05"/>
              <joint name="right-knee" type="hinge" ref="-45" range="-164 -37" damping="1" armature="0.09344"/>
              <geom type="mesh" mesh="right-knee"/>
              <body name="right-knee-spring" pos="0.06068 0.08241 0">
                <inertial pos="0.0836 0.0034 0" mass="0.186" fullinertia="5.215e-05 0.00041205 0.0003669 6.87e-06 0 0"/>
                <geom type="mesh" mesh="right-knee-spring"/>
              </body>
              <body name="right-shin" pos="0.06068 0.04741 0">
                <inertial pos="0.18338 0.001169 -0.0002123" mass="0.577" fullinertia="0.00035939 0.014728 0.014707 -0.00020981 -2.266e-05 1.2e-07"/>
                <joint name="right-shin" type="hinge" range="-20 20" stiffness="1500" damping="0.1"/>
                <geom type="mesh" mesh="right-shin"/>
                <geom type="capsule" size="0.04" fromto="0 0 0 0.43476 0.02 0" class="collision-right"/>
                <body name="right-tarsus" pos="0.43476 0.02 0" xyaxes="0.52992 0.84805 0 -0.84805 0.52992 0">
                  <inertial pos="0.11046 -0.03058 0.00131" mass="0.782" fullinertia="0.00039238 0.013595 0.013674 0.00023651 4.987e-05 4.82e-06"/>
                  <joint name="right-tarsus" type="hinge" ref="58" range="50 170" damping="0.1"/>
                  <geom type="mesh" mesh="right-tarsus"/>
                  <geom type="capsule" size="0.04" fromto="-0.01269 -0.03059 -0.00092 0.408 -0.04 0" class="collision-right"/>
                  <body name="right-heel-spring" pos="-0.01269 -0.03059 -0.00092" xyaxes="-0.91211 0.40829 -0.036948 -0.40992 -0.90952 0.068841">
                    <inertial pos="0.081 0.0022 0" mass="0.126" fullinertia="2.959e-05 0.00022231 0.0002007 7.15e-06 6e-07 -1e-07"/>
                    <joint name="right-heel-spring" type="hinge" limited="false" stiffness="1250"/>
                    <geom type="mesh" mesh="right-heel-spring"/>
                  </body>
                  <body name="right-foot-crank" pos="0.058 -0.034 -0.02275">
                    <inertial pos="0.00493 2e-05 0.00215" mass="0.1261" fullinertia="2.6941e-05 4.9621e-05 6.3362e-05 -2.1e-09 3.9623e-06 1.09e-08"/>
                    <joint name="right-foot-crank" type="hinge" range="-140 -30" damping="1"/>
                    <geom type="mesh" mesh="right-foot-crank"/>
                    <body name="right-plantar-rod" pos="0.055 0 0.00791">
                      <inertial pos="0.17792 0 0" mass="0.1186" fullinertia="2.779e-06 0.001774 0.001775 -2.34e-08 8.1e-09 0"/>
                      <joint name="right-plantar-rod" type="hinge" limited="false"/>
                      <geom type="mesh" mesh="right-plantar-rod"/>
                    </body>
                  </body>
                  <body name="right-foot" pos="0.408 -0.04 0">
                    <inertial pos="0.00474 0.02748 0.00014" mass="0.1498" fullinertia="0.00017388 0.00016793 0.00033261 0.00011814 -1.36e-06 4e-07"/>
                    <joint name="right-foot" type="hinge" range="-140 -30" damping="1" armature="0.01225"/>
                    <geom type="mesh" mesh="right-foot"/>
                    <geom type="capsule" size="0.02" fromto="-0.052821 0.092622 0 0.069746 -0.010224 0" class="collision-right"/>
                  </body>
                </body>
              </body>
            </body>
          </body>
        </body>
      </body>
    </body>
    <!-- Add any other moving bodies after the Cassie definition -->
    <!-- <body name='box' pos='2 0 0.2'> -->
    <!--   <freejoint/> -->
    <!--   <geom type='box' size='0.1 0.1 0.1' mass='3' class='obstacle'/> -->
    <!-- </body> -->
    <geom name="waypoint1" pos="0.2507969618513704 -0.21410586447363225 1.01 " size="0.03 0.03 0.03" type="sphere" contype="0" rgba="1 0.9 0 0.7"/>
    <geom name="waypoint2" pos="0.37318701631545353 -0.32257767807452176 1.01 " size="0.03 0.03 0.03" type="sphere" contype="0" rgba="1 0.9 0 0.7"/>
    <geom name="waypoint3" pos="0.493454025216966 -0.4319816503989209 1.01 " size="0.03 0.03 0.03" type="sphere" contype="0" rgba="1 0.9 0 0.7"/>
    <geom name="waypoint4" pos="0.6115099176147768 -0.5423074598074162 1.01 " size="0.03 0.03 0.03" type="sphere" contype="0" rgba="1 0.9 0 0.7"/>
    <geom name="waypoint5" pos="0.7272666225677614 -0.6535447846606033 1.01 " size="0.03 0.03 0.03" type="sphere" contype="0" rgba="1 0.9 0 0.7"/>
    <geom name="waypoint6" pos="0.8406360691347898 -0.7656833033190688 1.01 " size="0.03 0.03 0.03" type="sphere" contype="0" rgba="1 0.9 0 0.7"/>
    <geom name="waypoint7" pos="0.9515301863747342 -0.8787126941434024 1.01 " size="0.03 0.03 0.03" type="sphere" contype="0" rgba="1 0.9 0 0.7"/>
    <geom name="waypoint8" pos="1.0598609033464663 -0.9926226354942 1.01 " size="0.03 0.03 0.03" type="sphere" contype="0" rgba="1 0.9 0 0.7"/>
    <geom name="waypoint9" pos="1.1655401491088606 -1.1074028057320504 1.01 " size="0.03 0.03 0.03" type="sphere" contype="0" rgba="1 0.9 0 0.7"/>
    <geom name="waypoint10" pos="1.2684798527207863 -1.2230428832175433 1.01 " size="0.03 0.03 0.03" type="sphere" contype="0" rgba="1 0.9 0 0.7"/>
    <geom name="waypoint11" pos="1.3685919432411167 -1.3395325463112735 1.01 " size="0.03 0.03 0.03" type="sphere" contype="0" rgba="1 0.9 0 0.7"/>
    <geom name="waypoint12" pos="1.4657883497287232 -1.4568614733738305 1.01 " size="0.03 0.03 0.03" type="sphere" contype="0" rgba="1 0.9 0 0.7"/>
    <geom name="waypoint13" pos="1.5599810012424775 -1.5750193427658021 1.01 " size="0.03 0.03 0.03" type="sphere" contype="0" rgba="1 0.9 0 0.7"/>
    <geom name="waypoint14" pos="1.6510818268412537 -1.6939958328477849 1.01 " size="0.03 0.03 0.03" type="sphere" contype="0" rgba="1 0.9 0 0.7"/>
    <geom name="waypoint15" pos="1.738859779397262 -1.8154876059965073 1.01 " size="0.03 0.03 0.03" type="sphere" contype="0" rgba="1 0.9 0 0.7"/>
    <geom name="waypoint16" pos="1.822388393684416 -1.9510224097545217 1.01 " size="0.03 0.03 0.03" type="sphere" contype="0" rgba="1 0.9 0 0.7"/>
    <geom name="waypoint17" pos="1.9019755723323473 -2.100013649494807 1.01 " size="0.03 0.03 0.03" type="sphere" contype="0" rgba="1 0.9 0 0.7"/>
    <geom name="waypoint18" pos="1.9781787867055725 -2.259117114048877 1.01 " size="0.03 0.03 0.03" type="sphere" contype="0" rgba="1 0.9 0 0.7"/>
    <geom name="waypoint19" pos="2.051555508168607 -2.424988592248249 1.01 " size="0.03 0.03 0.03" type="sphere" contype="0" rgba="1 0.9 0 0.7"/>
    <geom name="waypoint20" pos="2.122663208085971 -2.5942838729244335 1.01 " size="0.03 0.03 0.03" type="sphere" contype="0" rgba="1 0.9 0 0.7"/>
    <geom name="waypoint21" pos="2.1920593578221808 -2.763658744908956 1.01 " size="0.03 0.03 0.03" type="sphere" contype="0" rgba="1 0.9 0 0.7"/>
    <geom name="waypoint22" pos="2.260301428741752 -2.929768997033321 1.01 " size="0.03 0.03 0.03" type="sphere" contype="0" rgba="1 0.9 0 0.7"/>
    <geom name="waypoint23" pos="2.3279468922092 -3.0892704181290442 1.01 " size="0.03 0.03 0.03" type="sphere" contype="0" rgba="1 0.9 0 0.7"/>
    <geom name="waypoint24" pos="2.3955532195890465 -3.2388187970276454 1.01 " size="0.03 0.03 0.03" type="sphere" contype="0" rgba="1 0.9 0 0.7"/>
    <geom name="waypoint25" pos="2.4636778822458063 -3.375069922560639 1.01 " size="0.03 0.03 0.03" type="sphere" contype="0" rgba="1 0.9 0 0.7"/>
    <geom name="waypoint26" pos="2.5328783515439963 -3.494679583559534 1.01 " size="0.03 0.03 0.03" type="sphere" contype="0" rgba="1 0.9 0 0.7"/>
    <geom name="waypoint27" pos="2.6037120988481313 -3.5943035688558487 1.01 " size="0.03 0.03 0.03" type="sphere" contype="0" rgba="1 0.9 0 0.7"/>
    <geom name="waypoint28" pos="2.6767365955227334 -3.670597667281098 1.01 " size="0.03 0.03 0.03" type="sphere" contype="0" rgba="1 0.9 0 0.7"/>
    <geom name="waypoint29" pos="2.752509312932314 -3.720217667666796 1.01 " size="0.03 0.03 0.03" type="sphere" contype="0" rgba="1 0.9 0 0.7"/>
    <geom name="waypoint30" pos="2.8315877224413954 -3.7398193588444575 1.01 " size="0.03 0.03 0.03" type="sphere" contype="0" rgba="1 0.9 0 0.7"/>
    <geom name="waypoint31" pos="2.9142626876596807 -3.7393301976353 1.01 " size="0.03 0.03 0.03" type="sphere" contype="0" rgba="1 0.9 0 0.7"/>
    <geom name="waypoint32" pos="3.000101534909021 -3.7370238007500394 1.01 " size="0.03 0.03 0.03" type="sphere" contype="0" rgba="1 0.9 0 0.7"/>
    <geom name="waypoint33" pos="3.0886645288162975 -3.733108431753688 1.01 " size="0.03 0.03 0.03" type="sphere" contype="0" rgba="1 0.9 0 0.7"/>
    <geom name="waypoint34" pos="3.1795137188996248 -3.72762074544306 1.01 " size="0.03 0.03 0.03" type="sphere" contype="0" rgba="1 0.9 0 0.7"/>
    <geom name="waypoint35" pos="3.272211154677122 -3.7205973966149695 1.01 " size="0.03 0.03 0.03" type="sphere" contype="0" rgba="1 0.9 0 0.7"/>
    <geom name="waypoint36" pos="3.366318885666906 -3.7120750400662432 1.01 " size="0.03 0.03 0.03" type="sphere" contype="0" rgba="1 0.9 0 0.7"/>
    <geom name="waypoint37" pos="3.4613989613870952 -3.7020903305936894 1.01 " size="0.03 0.03 0.03" type="sphere" contype="0" rgba="1 0.9 0 0.7"/>
    <geom name="waypoint38" pos="3.557013431355805 -3.690679922994135 1.01 " size="0.03 0.03 0.03" type="sphere" contype="0" rgba="1 0.9 0 0.7"/>
    <geom name="waypoint39" pos="3.652724345091156 -3.677880472064389 1.01 " size="0.03 0.03 0.03" type="sphere" contype="0" rgba="1 0.9 0 0.7"/>
    <geom name="waypoint40" pos="3.7480937521112585 -3.6637286326012735 1.01 " size="0.03 0.03 0.03" type="sphere" contype="0" rgba="1 0.9 0 0.7"/>
    <geom name="waypoint41" pos="3.8426837019342375 -3.6482610594016096 1.01 " size="0.03 0.03 0.03" type="sphere" contype="0" rgba="1 0.9 0 0.7"/>
    <geom name="waypoint42" pos="3.936056244078209 -3.631514407262205 1.01 " size="0.03 0.03 0.03" type="sphere" contype="0" rgba="1 0.9 0 0.7"/>
    <geom name="waypoint43" pos="4.027773428061284 -3.613525330979888 1.01 " size="0.03 0.03 0.03" type="sphere" contype="0" rgba="1 0.9 0 0.7"/>
    <geom name="waypoint44" pos="4.117397303401589 -3.594330485351468 1.01 " size="0.03 0.03 0.03" type="sphere" contype="0" rgba="1 0.9 0 0.7"/>
    <geom name="waypoint45" pos="4.204489919617234 -3.573966525173771 1.01 " size="0.03 0.03 0.03" type="sphere" contype="0" rgba="1 0.9 0 0.7"/>
    <geom name="waypoint46" pos="4.2892873247015935 -3.550633727974065 1.01 " size="0.03 0.03 0.03" type="sphere" contype="0" rgba="1 0.9 0 0.7"/>
    <geom name="waypoint47" pos="4.379201750924373 -3.502662903034393 1.01 " size="0.03 0.03 0.03" type="sphere" contype="0" rgba="1 0.9 0 0.7"/>
    <geom name="waypoint48" pos="4.475015364812164 -3.425788781842712 1.01 " size="0.03 0.03 0.03" type="sphere" contype="0" rgba="1 0.9 0 0.7"/>
    <geom name="waypoint49" pos="4.574974705346718 -3.322579247930271 1.01 " size="0.03 0.03 0.03" type="sphere" contype="0" rgba="1 0.9 0 0.7"/>
    <geom name="waypoint50" pos="4.677326311509785 -3.195602184828323 1.01 " size="0.03 0.03 0.03" type="sphere" contype="0" rgba="1 0.9 0 0.7"/>
    <geom name="waypoint51" pos="4.78031672228311 -3.0474254760681174 1.01 " size="0.03 0.03 0.03" type="sphere" contype="0" rgba="1 0.9 0 0.7"/>
    <geom name="waypoint52" pos="4.882192476648445 -2.8806170051809086 1.01 " size="0.03 0.03 0.03" type="sphere" contype="0" rgba="1 0.9 0 0.7"/>
    <geom name="waypoint53" pos="4.981200113587538 -2.6977446556979454 1.01 " size="0.03 0.03 0.03" type="sphere" contype="0" rgba="1 0.9 0 0.7"/>
    <geom name="waypoint54" pos="5.075586172082136 -2.5013763111504748 1.01 " size="0.03 0.03 0.03" type="sphere" contype="0" rgba="1 0.9 0 0.7"/>
    <geom name="waypoint55" pos="5.163597191113992 -2.294079855069759 1.01 " size="0.03 0.03 0.03" type="sphere" contype="0" rgba="1 0.9 0 0.7"/>
    <geom name="waypoint56" pos="5.243479709664848 -2.078423170987035 1.01 " size="0.03 0.03 0.03" type="sphere" contype="0" rgba="1 0.9 0 0.7"/>
    <geom name="waypoint57" pos="5.3134802667164625 -1.8569741424335613 1.01 " size="0.03 0.03 0.03" type="sphere" contype="0" rgba="1 0.9 0 0.7"/>
    <geom name="waypoint58" pos="5.371845401250578 -1.632300652940586 1.01 " size="0.03 0.03 0.03" type="sphere" contype="0" rgba="1 0.9 0 0.7"/>
    <geom name="waypoint59" pos="5.416821652248942 -1.406970586039364 1.01 " size="0.03 0.03 0.03" type="sphere" contype="0" rgba="1 0.9 0 0.7"/>
    <geom name="waypoint60" pos="5.446655558693309 -1.1835518252611459 1.01 " size="0.03 0.03 0.03" type="sphere" contype="0" rgba="1 0.9 0 0.7"/>
    <geom name="waypoint61" pos="5.459593659565421 -0.9646122541371778 1.01 " size="0.03 0.03 0.03" type="sphere" contype="0" rgba="1 0.9 0 0.7"/>
    <geom name="waypoint62" pos="5.4565373974416636 -0.7329759177553098 1.01 " size="0.03 0.03 0.03" type="sphere" contype="0" rgba="1 0.9 0 0.7"/>
    <geom name="waypoint63" pos="5.44307404033615 -0.4529485402055596 1.01 " size="0.03 0.03 0.03" type="sphere" contype="0" rgba="1 0.9 0 0.7"/>
    <geom name="waypoint64" pos="5.420829845641616 -0.13223455237368853 1.01 " size="0.03 0.03 0.03" type="sphere" contype="0" rgba="1 0.9 0 0.7"/>
    <geom name="waypoint65" pos="5.391272362815837 0.22006274769497305 1.01 " size="0.03 0.03 0.03" type="sphere" contype="0" rgba="1 0.9 0 0.7"/>
    <geom name="waypoint66" pos="5.3558691413165835 0.5948400619550789 1.01 " size="0.03 0.03 0.03" type="sphere" contype="0" rgba="1 0.9 0 0.7"/>
    <geom name="waypoint67" pos="5.3160877306016365 0.9829940923612916 1.01 " size="0.03 0.03 0.03" type="sphere" contype="0" rgba="1 0.9 0 0.7"/>
    <geom name="waypoint68" pos="5.273395680128768 1.3754215408682686 1.01 " size="0.03 0.03 0.03" type="sphere" contype="0" rgba="1 0.9 0 0.7"/>
    <geom name="waypoint69" pos="5.229260539355755 1.7630191094306689 1.01 " size="0.03 0.03 0.03" type="sphere" contype="0" rgba="1 0.9 0 0.7"/>
    <geom name="waypoint70" pos="5.185149857740369 2.1366835000031585 1.01 " size="0.03 0.03 0.03" type="sphere" contype="0" rgba="1 0.9 0 0.7"/>
    <geom name="waypoint71" pos="5.142531184740391 2.4873114145403985 1.01 " size="0.03 0.03 0.03" type="sphere" contype="0" rgba="1 0.9 0 0.7"/>
    <geom name="waypoint72" pos="5.102872069813591 2.805799554997048 1.01 " size="0.03 0.03 0.03" type="sphere" contype="0" rgba="1 0.9 0 0.7"/>
    <geom name="waypoint73" pos="5.067640062417746 3.083044623327755 1.01 " size="0.03 0.03 0.03" type="sphere" contype="0" rgba="1 0.9 0 0.7"/>
    <geom name="waypoint74" pos="5.038302712010633 3.3099433214871987 1.01 " size="0.03 0.03 0.03" type="sphere" contype="0" rgba="1 0.9 0 0.7"/>
    <geom name="waypoint75" pos="5.016327568050025 3.4773923514300304 1.01 " size="0.03 0.03 0.03" type="sphere" contype="0" rgba="1 0.9 0 0.7"/>
    <geom name="waypoint76" pos="5.003182179993696 3.5762884151109087 1.01 " size="0.03 0.03 0.03" type="sphere" contype="0" rgba="1 0.9 0 0.7"/>
    <geom name="waypoint77" pos="5.001521236634439 3.599974399029678 1.01 " size="0.03 0.03 0.03" type="sphere" contype="0" rgba="1 0.9 0 0.7"/>
    <geom name="waypoint78" pos="5.0389155644162 3.59932282588468 1.01 " size="0.03 0.03 0.03" type="sphere" contype="0" rgba="1 0.9 0 0.7"/>
    <geom name="waypoint79" pos="5.1220589195841635 3.5978006474262094 1.01 " size="0.03 0.03 0.03" type="sphere" contype="0" rgba="1 0.9 0 0.7"/>
    <geom name="waypoint80" pos="5.245137278449152 3.595418941171312 1.01 " size="0.03 0.03 0.03" type="sphere" contype="0" rgba="1 0.9 0 0.7"/>
    <geom name="waypoint81" pos="5.402336617321991 3.592188784637028 1.01 " size="0.03 0.03 0.03" type="sphere" contype="0" rgba="1 0.9 0 0.7"/>
    <geom name="waypoint82" pos="5.5878429125135 3.5881212553403983 1.01 " size="0.03 0.03 0.03" type="sphere" contype="0" rgba="1 0.9 0 0.7"/>
    <geom name="waypoint83" pos="5.795842140334508 3.5832274307984697 1.01 " size="0.03 0.03 0.03" type="sphere" contype="0" rgba="1 0.9 0 0.7"/>
    <geom name="waypoint84" pos="6.020520277095835 3.577518388528283 1.01 " size="0.03 0.03 0.03" type="sphere" contype="0" rgba="1 0.9 0 0.7"/>
    <geom name="waypoint85" pos="6.256063299108309 3.571005206046877 1.01 " size="0.03 0.03 0.03" type="sphere" contype="0" rgba="1 0.9 0 0.7"/>
    <geom name="waypoint86" pos="6.496657182682745 3.5636989608712972 1.01 " size="0.03 0.03 0.03" type="sphere" contype="0" rgba="1 0.9 0 0.7"/>
    <geom name="waypoint87" pos="6.736487904129975 3.555610730518587 1.01 " size="0.03 0.03 0.03" type="sphere" contype="0" rgba="1 0.9 0 0.7"/>
    <geom name="waypoint88" pos="6.96974143976082 3.546751592505789 1.01 " size="0.03 0.03 0.03" type="sphere" contype="0" rgba="1 0.9 0 0.7"/>
    <geom name="waypoint89" pos="7.190603765886103 3.537132624349941 1.01 " size="0.03 0.03 0.03" type="sphere" contype="0" rgba="1 0.9 0 0.7"/>
    <geom name="waypoint90" pos="7.393260858816646 3.526764903568086 1.01 " size="0.03 0.03 0.03" type="sphere" contype="0" rgba="1 0.9 0 0.7"/>
    <geom name="waypoint91" pos="7.571898694863274 3.5156595076772734 1.01 " size="0.03 0.03 0.03" type="sphere" contype="0" rgba="1 0.9 0 0.7"/>
    <geom name="waypoint92" pos="7.720703250336809 3.50382751419454 1.01 " size="0.03 0.03 0.03" type="sphere" contype="0" rgba="1 0.9 0 0.7"/>
    <geom name="waypoint93" pos="7.84398102737199 3.4824211101767 1.01 " size="0.03 0.03 0.03" type="sphere" contype="0" rgba="1 0.9 0 0.7"/>
    <geom name="waypoint94" pos="7.968417205309096 3.426375092109788 1.01 " size="0.03 0.03 0.03" type="sphere" contype="0" rgba="1 0.9 0 0.7"/>
    <geom name="waypoint95" pos="8.094467956195619 3.3371897188676107 1.01 " size="0.03 0.03 0.03" type="sphere" contype="0" rgba="1 0.9 0 0.7"/>
    <geom name="waypoint96" pos="8.220594291719385 3.218226099021132 1.01 " size="0.03 0.03 0.03" type="sphere" contype="0" rgba="1 0.9 0 0.7"/>
    <geom name="waypoint97" pos="8.345257223568217 3.072845341141296 1.01 " size="0.03 0.03 0.03" type="sphere" contype="0" rgba="1 0.9 0 0.7"/>
    <geom name="waypoint98" pos="8.466917763429931 2.9044085537990565 1.01 " size="0.03 0.03 0.03" type="sphere" contype="0" rgba="1 0.9 0 0.7"/>
    <geom name="waypoint99" pos="8.584036922992345 2.7162768455653654 1.01 " size="0.03 0.03 0.03" type="sphere" contype="0" rgba="1 0.9 0 0.7"/>
    <geom name="waypoint100" pos="8.695075713943286 2.511811325011178 1.01 " size="0.03 0.03 0.03" type="sphere" contype="0" rgba="1 0.9 0 0.7"/>
    <geom name="waypoint101" pos="8.798495147970574 2.294373100707441 1.01 " size="0.03 0.03 0.03" type="sphere" contype="0" rgba="1 0.9 0 0.7"/>
    <geom name="waypoint102" pos="8.892756236762033 2.0673232812251072 1.01 " size="0.03 0.03 0.03" type="sphere" contype="0" rgba="1 0.9 0 0.7"/>
    <geom name="waypoint103" pos="8.97631999200547 1.834022975135133 1.01 " size="0.03 0.03 0.03" type="sphere" contype="0" rgba="1 0.9 0 0.7"/>
    <geom name="waypoint104" pos="9.047647425388723 1.5978332910084645 1.01 " size="0.03 0.03 0.03" type="sphere" contype="0" rgba="1 0.9 0 0.7"/>
    <geom name="waypoint105" pos="9.105199548599604 1.3621153374160568 1.01 " size="0.03 0.03 0.03" type="sphere" contype="0" rgba="1 0.9 0 0.7"/>
    <geom name="waypoint106" pos="9.147437373325936 1.1302302229288603 1.01 " size="0.03 0.03 0.03" type="sphere" contype="0" rgba="1 0.9 0 0.7"/>
    <geom name="waypoint107" pos="9.172821911255536 0.9055390561178278 1.01 " size="0.03 0.03 0.03" type="sphere" contype="0" rgba="1 0.9 0 0.7"/>
    <geom name="waypoint108" pos="9.179870323215882 0.6909648516295145 1.01 " size="0.03 0.03 0.03" type="sphere" contype="0" rgba="1 0.9 0 0.7"/>
    <geom name="waypoint109" pos="9.17145734803162 0.4614481743502256 1.01 " size="0.03 0.03 0.03" type="sphere" contype="0" rgba="1 0.9 0 0.7"/>
    <geom name="waypoint110" pos="9.151183453799735 0.20470798066460813 1.01 " size="0.03 0.03 0.03" type="sphere" contype="0" rgba="1 0.9 0 0.7"/>
    <geom name="waypoint111" pos="9.12083522246882 -0.07391846535186807 1.01 " size="0.03 0.03 0.03" type="sphere" contype="0" rgba="1 0.9 0 0.7"/>
    <geom name="waypoint112" pos="9.08219923598748 -0.3690938996237581 1.01 " size="0.03 0.03 0.03" type="sphere" contype="0" rgba="1 0.9 0 0.7"/>
    <geom name="waypoint113" pos="9.0370620763043 -0.6754810580756044 1.01 " size="0.03 0.03 0.03" type="sphere" contype="0" rgba="1 0.9 0 0.7"/>
    <geom name="waypoint114" pos="8.987210325367883 -0.9877426766319513 1.01 " size="0.03 0.03 0.03" type="sphere" contype="0" rgba="1 0.9 0 0.7"/>
    <geom name="waypoint115" pos="8.934430565126819 -1.3005414912173414 1.01 " size="0.03 0.03 0.03" type="sphere" contype="0" rgba="1 0.9 0 0.7"/>
    <geom name="waypoint116" pos="8.88050937752971 -1.6085402377563245 1.01 " size="0.03 0.03 0.03" type="sphere" contype="0" rgba="1 0.9 0 0.7"/>
    <geom name="waypoint117" pos="8.82723334452515 -1.9064016521734377 1.01 " size="0.03 0.03 0.03" type="sphere" contype="0" rgba="1 0.9 0 0.7"/>
    <geom name="waypoint118" pos="8.77638904806173 -2.188788470393229 1.01 " size="0.03 0.03 0.03" type="sphere" contype="0" rgba="1 0.9 0 0.7"/>
    <geom name="waypoint119" pos="8.729763070088058 -2.450363428340239 1.01 " size="0.03 0.03 0.03" type="sphere" contype="0" rgba="1 0.9 0 0.7"/>
    <geom name="waypoint120" pos="8.68914199255272 -2.685789261939013 1.01 " size="0.03 0.03 0.03" type="sphere" contype="0" rgba="1 0.9 0 0.7"/>
    <geom name="waypoint121" pos="8.656312397404314 -2.889728707114101 1.01 " size="0.03 0.03 0.03" type="sphere" contype="0" rgba="1 0.9 0 0.7"/>
    <geom name="waypoint122" pos="8.633060866591435 -3.0568444997900452 1.01 " size="0.03 0.03 0.03" type="sphere" contype="0" rgba="1 0.9 0 0.7"/>
    <geom name="waypoint123" pos="8.62117398206268 -3.1817993758913894 1.01 " size="0.03 0.03 0.03" type="sphere" contype="0" rgba="1 0.9 0 0.7"/>
    <geom name="waypoint124" pos="8.633560520064385 -3.267552937010485 1.01 " size="0.03 0.03 0.03" type="sphere" contype="0" rgba="1 0.9 0 0.7"/>
    <geom name="waypoint125" pos="8.715592646952652 -3.3468301704580767 1.01 " size="0.03 0.03 0.03" type="sphere" contype="0" rgba="1 0.9 0 0.7"/>
    <geom name="waypoint126" pos="8.863833901754758 -3.423266223395492 1.01 " size="0.03 0.03 0.03" type="sphere" contype="0" rgba="1 0.9 0 0.7"/>
    <geom name="waypoint127" pos="9.068939883009369 -3.496469025255281 1.01 " size="0.03 0.03 0.03" type="sphere" contype="0" rgba="1 0.9 0 0.7"/>
    <geom name="waypoint128" pos="9.321566189255167 -3.566046505470002 1.01 " size="0.03 0.03 0.03" type="sphere" contype="0" rgba="1 0.9 0 0.7"/>
    <geom name="waypoint129" pos="9.612368419030798 -3.631606593472216 1.01 " size="0.03 0.03 0.03" type="sphere" contype="0" rgba="1 0.9 0 0.7"/>
    <geom name="waypoint130" pos="9.932002170874968 -3.6927572186944833 1.01 " size="0.03 0.03 0.03" type="sphere" contype="0" rgba="1 0.9 0 0.7"/>
    <geom name="waypoint131" pos="10.271123043326332 -3.7491063105693514 1.01 " size="0.03 0.03 0.03" type="sphere" contype="0" rgba="1 0.9 0 0.7"/>
    <geom name="waypoint132" pos="10.62038663492356 -3.8002617985293847 1.01 " size="0.03 0.03 0.03" type="sphere" contype="0" rgba="1 0.9 0 0.7"/>
    <geom name="waypoint133" pos="10.970448544205325 -3.845831612007137 1.01 " size="0.03 0.03 0.03" type="sphere" contype="0" rgba="1 0.9 0 0.7"/>
    <geom name="waypoint134" pos="11.311964369710296 -3.8854236804351694 1.01 " size="0.03 0.03 0.03" type="sphere" contype="0" rgba="1 0.9 0 0.7"/>
    <geom name="waypoint135" pos="11.635589709977149 -3.9186459332460366 1.01 " size="0.03 0.03 0.03" type="sphere" contype="0" rgba="1 0.9 0 0.7"/>
    <geom name="waypoint136" pos="11.931980163544548 -3.9451062998723 1.01 " size="0.03 0.03 0.03" type="sphere" contype="0" rgba="1 0.9 0 0.7"/>
    <geom name="waypoint137" pos="12.191791328951178 -3.9644127097465094 1.01 " size="0.03 0.03 0.03" type="sphere" contype="0" rgba="1 0.9 0 0.7"/>
    <geom name="waypoint138" pos="12.405678804735688 -3.9761730923012313 1.01 " size="0.03 0.03 0.03" type="sphere" contype="0" rgba="1 0.9 0 0.7"/>
    <geom name="waypoint139" pos="12.564334128068527 -3.9799625779612646 1.01 " size="0.03 0.03 0.03" type="sphere" contype="0" rgba="1 0.9 0 0.7"/>
    <geom name="waypoint140" pos="12.6943069266597 -3.945364794665277 1.01 " size="0.03 0.03 0.03" type="sphere" contype="0" rgba="1 0.9 0 0.7"/>
    <geom name="waypoint141" pos="12.823426318614272 -3.851031799369226 1.01 " size="0.03 0.03 0.03" type="sphere" contype="0" rgba="1 0.9 0 0.7"/>
    <geom name="waypoint142" pos="12.950578940734076 -3.7044223007156503 1.01 " size="0.03 0.03 0.03" type="sphere" contype="0" rgba="1 0.9 0 0.7"/>
    <geom name="waypoint143" pos="13.074651429820957 -3.5129950073470884 1.01 " size="0.03 0.03 0.03" type="sphere" contype="0" rgba="1 0.9 0 0.7"/>
    <geom name="waypoint144" pos="13.194530422676767 -3.284208627906078 1.01 " size="0.03 0.03 0.03" type="sphere" contype="0" rgba="1 0.9 0 0.7"/>
    <geom name="waypoint145" pos="13.309102556103348 -3.025521871035162 1.01 " size="0.03 0.03 0.03" type="sphere" contype="0" rgba="1 0.9 0 0.7"/>
    <geom name="waypoint146" pos="13.417254466902545 -2.7443934453768764 1.01 " size="0.03 0.03 0.03" type="sphere" contype="0" rgba="1 0.9 0 0.7"/>
    <geom name="waypoint147" pos="13.5178727918762 -2.44828205957376 1.01 " size="0.03 0.03 0.03" type="sphere" contype="0" rgba="1 0.9 0 0.7"/>
    <geom name="waypoint148" pos="13.609844167826173 -2.144646422268348 1.01 " size="0.03 0.03 0.03" type="sphere" contype="0" rgba="1 0.9 0 0.7"/>
    <geom name="waypoint149" pos="13.692055231554288 -1.8409452421031804 1.01 " size="0.03 0.03 0.03" type="sphere" contype="0" rgba="1 0.9 0 0.7"/>
    <geom name="waypoint150" pos="13.763392619862408 -1.5446372277207967 1.01 " size="0.03 0.03 0.03" type="sphere" contype="0" rgba="1 0.9 0 0.7"/>
    <geom name="waypoint151" pos="13.822742969552364 -1.263181087763737 1.01 " size="0.03 0.03 0.03" type="sphere" contype="0" rgba="1 0.9 0 0.7"/>
    <geom name="waypoint152" pos="13.868992917426018 -1.004035530874539 1.01 " size="0.03 0.03 0.03" type="sphere" contype="0" rgba="1 0.9 0 0.7"/>
    <geom name="waypoint153" pos="13.901029100285196 -0.774659265695739 1.01 " size="0.03 0.03 0.03" type="sphere" contype="0" rgba="1 0.9 0 0.7"/>
    <geom name="waypoint154" pos="13.91773815493176 -0.5825110008698821 1.01 " size="0.03 0.03 0.03" type="sphere" contype="0" rgba="1 0.9 0 0.7"/>
    <geom name="waypoint155" pos="13.91442398625425 -0.4305876293593798 1.01 " size="0.03 0.03 0.03" type="sphere" contype="0" rgba="1 0.9 0 0.7"/>
    <geom name="waypoint156" pos="13.869520025317687 -0.2942948430961643 1.01 " size="0.03 0.03 0.03" type="sphere" contype="0" rgba="1 0.9 0 0.7"/>
    <geom name="waypoint157" pos="13.784855045050147 -0.16757004413610946 1.01 " size="0.03 0.03 0.03" type="sphere" contype="0" rgba="1 0.9 0 0.7"/>
    <geom name="waypoint158" pos="13.666745888769873 -0.04913372300138086 1.01 " size="0.03 0.03 0.03" type="sphere" contype="0" rgba="1 0.9 0 0.7"/>
    <geom name="waypoint159" pos="13.52150939979511 0.06229362978586295 1.01 " size="0.03 0.03 0.03" type="sphere" contype="0" rgba="1 0.9 0 0.7"/>
    <geom name="waypoint160" pos="13.355462421444116 0.16799152370345818 1.01 " size="0.03 0.03 0.03" type="sphere" contype="0" rgba="1 0.9 0 0.7"/>
    <geom name="waypoint161" pos="13.17492179703514 0.26923946822924094 1.01 " size="0.03 0.03 0.03" type="sphere" contype="0" rgba="1 0.9 0 0.7"/>
    <geom name="waypoint162" pos="12.986204369886423 0.3673169728410493 1.01 " size="0.03 0.03 0.03" type="sphere" contype="0" rgba="1 0.9 0 0.7"/>
    <geom name="waypoint163" pos="12.795626983316227 0.463503547016721 1.01 " size="0.03 0.03 0.03" type="sphere" contype="0" rgba="1 0.9 0 0.7"/>
    <geom name="waypoint164" pos="12.609506480642795 0.5590787002340925 1.01 " size="0.03 0.03 0.03" type="sphere" contype="0" rgba="1 0.9 0 0.7"/>
    <geom name="waypoint165" pos="12.434159705184381 0.6553219419710049 1.01 " size="0.03 0.03 0.03" type="sphere" contype="0" rgba="1 0.9 0 0.7"/>
    <geom name="waypoint166" pos="12.275903500259222 0.7535127817052931 1.01 " size="0.03 0.03 0.03" type="sphere" contype="0" rgba="1 0.9 0 0.7"/>
    <geom name="waypoint167" pos="12.141054709185587 0.854930728914793 1.01 " size="0.03 0.03 0.03" type="sphere" contype="0" rgba="1 0.9 0 0.7"/>
    <geom name="waypoint168" pos="12.035930175281715 0.9608552930773476 1.01 " size="0.03 0.03 0.03" type="sphere" contype="0" rgba="1 0.9 0 0.7"/>
    <geom name="waypoint169" pos="11.966846741865853 1.0725659836707901 1.01 " size="0.03 0.03 0.03" type="sphere" contype="0" rgba="1 0.9 0 0.7"/>
    <geom name="waypoint170" pos="11.94012125225626 1.191342310172958 1.01 " size="0.03 0.03 0.03" type="sphere" contype="0" rgba="1 0.9 0 0.7"/>
    <geom name="waypoint171" pos="11.956296308803164 1.3239940752980106 1.01 " size="0.03 0.03 0.03" type="sphere" contype="0" rgba="1 0.9 0 0.7"/>
    <geom name="waypoint172" pos="12.007537932555472 1.4757862052226367 1.01 " size="0.03 0.03 0.03" type="sphere" contype="0" rgba="1 0.9 0 0.7"/>
    <geom name="waypoint173" pos="12.0895112774448 1.6427954376215066 1.01 " size="0.03 0.03 0.03" type="sphere" contype="0" rgba="1 0.9 0 0.7"/>
    <geom name="waypoint174" pos="12.197905813088548 1.8210624974803375 1.01 " size="0.03 0.03 0.03" type="sphere" contype="0" rgba="1 0.9 0 0.7"/>
    <geom name="waypoint175" pos="12.32841100910412 2.006628109784838 1.01 " size="0.03 0.03 0.03" type="sphere" contype="0" rgba="1 0.9 0 0.7"/>
    <geom name="waypoint176" pos="12.47671633510892 2.195532999520724 1.01 " size="0.03 0.03 0.03" type="sphere" contype="0" rgba="1 0.9 0 0.7"/>
    <geom name="waypoint177" pos="12.638511260720342 2.3838178916737025 1.01 " size="0.03 0.03 0.03" type="sphere" contype="0" rgba="1 0.9 0 0.7"/>
    <geom name="waypoint178" pos="12.809485255555792 2.5675235112294863 1.01 " size="0.03 0.03 0.03" type="sphere" contype="0" rgba="1 0.9 0 0.7"/>
    <geom name="waypoint179" pos="12.985327789232675 2.7426905831737916 1.01 " size="0.03 0.03 0.03" type="sphere" contype="0" rgba="1 0.9 0 0.7"/>
    <geom name="waypoint180" pos="13.161728331368387 2.905359832492328 1.01 " size="0.03 0.03 0.03" type="sphere" contype="0" rgba="1 0.9 0 0.7"/>
    <geom name="waypoint181" pos="13.33437635158033 3.0515719841708093 1.01 " size="0.03 0.03 0.03" type="sphere" contype="0" rgba="1 0.9 0 0.7"/>
    <geom name="waypoint182" pos="13.4989613194859 3.1773677631949457 1.01 " size="0.03 0.03 0.03" type="sphere" contype="0" rgba="1 0.9 0 0.7"/>
    <geom name="waypoint183" pos="13.65117270470251 3.2787878945504523 1.01 " size="0.03 0.03 0.03" type="sphere" contype="0" rgba="1 0.9 0 0.7"/>
    <geom name="waypoint184" pos="13.786699976847556 3.35187310322304 1.01 " size="0.03 0.03 0.03" type="sphere" contype="0" rgba="1 0.9 0 0.7"/>
    <geom name="waypoint185" pos="13.901232605538441 3.392664114198423 1.01 " size="0.03 0.03 0.03" type="sphere" contype="0" rgba="1 0.9 0 0.7"/>
    <geom name="waypoint186" pos="13.99267790048209 3.3962684203760087 1.01 " size="0.03 0.03 0.03" type="sphere" contype="0" rgba="1 0.9 0 0.7"/>
    <geom name="waypoint187" pos="14.080600924015425 3.3518681234380128 1.01 " size="0.03 0.03 0.03" type="sphere" contype="0" rgba="1 0.9 0 0.7"/>
    <geom name="waypoint188" pos="14.169751861376046 3.2611172248956155 1.01 " size="0.03 0.03 0.03" type="sphere" contype="0" rgba="1 0.9 0 0.7"/>
    <geom name="waypoint189" pos="14.259074313587734 3.1287632204557205 1.01 " size="0.03 0.03 0.03" type="sphere" contype="0" rgba="1 0.9 0 0.7"/>
    <geom name="waypoint190" pos="14.347511881674263 2.9595536058252585 1.01 " size="0.03 0.03 0.03" type="sphere" contype="0" rgba="1 0.9 0 0.7"/>
    <geom name="waypoint191" pos="14.434008166659405 2.758235876711133 1.01 " size="0.03 0.03 0.03" type="sphere" contype="0" rgba="1 0.9 0 0.7"/>
    <geom name="waypoint192" pos="14.517506769566928 2.529557528820261 1.01 " size="0.03 0.03 0.03" type="sphere" contype="0" rgba="1 0.9 0 0.7"/>
    <geom name="waypoint193" pos="14.596951291420607 2.278266057859559 1.01 " size="0.03 0.03 0.03" type="sphere" contype="0" rgba="1 0.9 0 0.7"/>
    <geom name="waypoint194" pos="14.671285333244217 2.0091089595359417 1.01 " size="0.03 0.03 0.03" type="sphere" contype="0" rgba="1 0.9 0 0.7"/>
    <geom name="waypoint195" pos="14.739452496061533 1.7268337295563219 1.01 " size="0.03 0.03 0.03" type="sphere" contype="0" rgba="1 0.9 0 0.7"/>
    <geom name="waypoint196" pos="14.800396380896313 1.4361878636276195 1.01 " size="0.03 0.03 0.03" type="sphere" contype="0" rgba="1 0.9 0 0.7"/>
    <geom name="waypoint197" pos="14.85306058877235 1.1419188574567443 1.01 " size="0.03 0.03 0.03" type="sphere" contype="0" rgba="1 0.9 0 0.7"/>
    <geom name="waypoint198" pos="14.896388720713402 0.8487742067506135 1.01 " size="0.03 0.03 0.03" type="sphere" contype="0" rgba="1 0.9 0 0.7"/>
    <geom name="waypoint199" pos="14.929324377743239 0.5615014072161432 1.01 " size="0.03 0.03 0.03" type="sphere" contype="0" rgba="1 0.9 0 0.7"/>
    <geom name="waypoint200" pos="14.950811160885642 0.284847954560254 1.01 " size="0.03 0.03 0.03" type="sphere" contype="0" rgba="1 0.9 0 0.7"/>
    <geom name="waypoint201" pos="14.959792671164381 0.023561344489849038 1.01 " size="0.03 0.03 0.03" type="sphere" contype="0" rgba="1 0.9 0 0.7"/>
    <geom name="waypoint202" pos="14.93614189132807 -0.23125271106785306 1.01 " size="0.03 0.03 0.03" type="sphere" contype="0" rgba="1 0.9 0 0.7"/>
    <geom name="waypoint203" pos="14.847137629518983 -0.5017634092605352 1.01 " size="0.03 0.03 0.03" type="sphere" contype="0" rgba="1 0.9 0 0.7"/>
    <geom name="waypoint204" pos="14.69863019755459 -0.7859210123654669 1.01 " size="0.03 0.03 0.03" type="sphere" contype="0" rgba="1 0.9 0 0.7"/>
    <geom name="waypoint205" pos="14.49735639659668 -1.081080421980788 1.01 " size="0.03 0.03 0.03" type="sphere" contype="0" rgba="1 0.9 0 0.7"/>
    <geom name="waypoint206" pos="14.250053027807052 -1.384596539704637 1.01 " size="0.03 0.03 0.03" type="sphere" contype="0" rgba="1 0.9 0 0.7"/>
    <geom name="waypoint207" pos="13.963456892347498 -1.6938242671351558 1.01 " size="0.03 0.03 0.03" type="sphere" contype="0" rgba="1 0.9 0 0.7"/>
    <geom name="waypoint208" pos="13.644304791379806 -2.006118505870486 1.01 " size="0.03 0.03 0.03" type="sphere" contype="0" rgba="1 0.9 0 0.7"/>
    <geom name="waypoint209" pos="13.299333526065784 -2.318834157508757 1.01 " size="0.03 0.03 0.03" type="sphere" contype="0" rgba="1 0.9 0 0.7"/>
    <geom name="waypoint210" pos="12.935279897567197 -2.629326123648133 1.01 " size="0.03 0.03 0.03" type="sphere" contype="0" rgba="1 0.9 0 0.7"/>
    <geom name="waypoint211" pos="12.558880707045866 -2.934949305886724 1.01 " size="0.03 0.03 0.03" type="sphere" contype="0" rgba="1 0.9 0 0.7"/>
    <geom name="waypoint212" pos="12.17687275566356 -3.233058605822705 1.01 " size="0.03 0.03 0.03" type="sphere" contype="0" rgba="1 0.9 0 0.7"/>
    <geom name="waypoint213" pos="11.795992844582102 -3.5210089250541774 1.01 " size="0.03 0.03 0.03" type="sphere" contype="0" rgba="1 0.9 0 0.7"/>
    <geom name="waypoint214" pos="11.422977774963265 -3.7961551651793073 1.01 " size="0.03 0.03 0.03" type="sphere" contype="0" rgba="1 0.9 0 0.7"/>
    <geom name="waypoint215" pos="11.064564347968831 -4.055852227796239 1.01 " size="0.03 0.03 0.03" type="sphere" contype="0" rgba="1 0.9 0 0.7"/>
    <geom name="waypoint216" pos="10.727489364760618 -4.297455014503091 1.01 " size="0.03 0.03 0.03" type="sphere" contype="0" rgba="1 0.9 0 0.7"/>
    <geom name="waypoint217" pos="10.41704775519804 -4.519561413807047 1.01 " size="0.03 0.03 0.03" type="sphere" contype="0" rgba="1 0.9 0 0.7"/>
    <geom name="waypoint218" pos="10.111460416228024 -4.742543252895662 1.01 " size="0.03 0.03 0.03" type="sphere" contype="0" rgba="1 0.9 0 0.7"/>
    <geom name="waypoint219" pos="9.801675257714782 -4.97208774301779 1.01 " size="0.03 0.03 0.03" type="sphere" contype="0" rgba="1 0.9 0 0.7"/>
    <geom name="waypoint220" pos="9.488209119205225 -5.205124793833809 1.01 " size="0.03 0.03 0.03" type="sphere" contype="0" rgba="1 0.9 0 0.7"/>
    <geom name="waypoint221" pos="9.171578840246193 -5.438584315004146 1.01 " size="0.03 0.03 0.03" type="sphere" contype="0" rgba="1 0.9 0 0.7"/>
    <geom name="waypoint222" pos="8.852301260384609 -5.669396216189173 1.01 " size="0.03 0.03 0.03" type="sphere" contype="0" rgba="1 0.9 0 0.7"/>
    <geom name="waypoint223" pos="8.530893219167318 -5.894490407049308 1.01 " size="0.03 0.03 0.03" type="sphere" contype="0" rgba="1 0.9 0 0.7"/>
    <geom name="waypoint224" pos="8.207871556141194 -6.110796797244964 1.01 " size="0.03 0.03 0.03" type="sphere" contype="0" rgba="1 0.9 0 0.7"/>
    <geom name="waypoint225" pos="7.883753110853144 -6.315245296436521 1.01 " size="0.03 0.03 0.03" type="sphere" contype="0" rgba="1 0.9 0 0.7"/>
    <geom name="waypoint226" pos="7.559054722850016 -6.5047658142844 1.01 " size="0.03 0.03 0.03" type="sphere" contype="0" rgba="1 0.9 0 0.7"/>
    <geom name="waypoint227" pos="7.234293231678714 -6.676288260448981 1.01 " size="0.03 0.03 0.03" type="sphere" contype="0" rgba="1 0.9 0 0.7"/>
    <geom name="waypoint228" pos="6.9099854768860896 -6.826742544590687 1.01 " size="0.03 0.03 0.03" type="sphere" contype="0" rgba="1 0.9 0 0.7"/>
    <geom name="waypoint229" pos="6.586648298019052 -6.9530585763699015 1.01 " size="0.03 0.03 0.03" type="sphere" contype="0" rgba="1 0.9 0 0.7"/>
    <geom name="waypoint230" pos="6.2647985346244495 -7.052166265447039 1.01 " size="0.03 0.03 0.03" type="sphere" contype="0" rgba="1 0.9 0 0.7"/>
    <geom name="waypoint231" pos="5.944953026249186 -7.120995521482493 1.01 " size="0.03 0.03 0.03" type="sphere" contype="0" rgba="1 0.9 0 0.7"/>
    <geom name="waypoint232" pos="5.627628612440128 -7.156476254136669 1.01 " size="0.03 0.03 0.03" type="sphere" contype="0" rgba="1 0.9 0 0.7"/>
    <geom name="waypoint233" pos="5.308596937297136 -7.165333200975434 1.01 " size="0.03 0.03 0.03" type="sphere" contype="0" rgba="1 0.9 0 0.7"/>
    <geom name="waypoint234" pos="4.976909835968687 -7.1723246207714935 1.01 " size="0.03 0.03 0.03" type="sphere" contype="0" rgba="1 0.9 0 0.7"/>
    <geom name="waypoint235" pos="4.63494307999695 -7.178855863170898 1.01 " size="0.03 0.03 0.03" type="sphere" contype="0" rgba="1 0.9 0 0.7"/>
    <geom name="waypoint236" pos="4.2858077551330735 -7.184922766880272 1.01 " size="0.03 0.03 0.03" type="sphere" contype="0" rgba="1 0.9 0 0.7"/>
    <geom name="waypoint237" pos="3.932614947128136 -7.190521170606271 1.01 " size="0.03 0.03 0.03" type="sphere" contype="0" rgba="1 0.9 0 0.7"/>
    <geom name="waypoint238" pos="3.5784757417332798 -7.1956469130555325 1.01 " size="0.03 0.03 0.03" type="sphere" contype="0" rgba="1 0.9 0 0.7"/>
    <geom name="waypoint239" pos="3.2265012246995863 -7.200295832934695 1.01 " size="0.03 0.03 0.03" type="sphere" contype="0" rgba="1 0.9 0 0.7"/>
    <geom name="waypoint240" pos="2.8798024817782 -7.204463768950401 1.01 " size="0.03 0.03 0.03" type="sphere" contype="0" rgba="1 0.9 0 0.7"/>
    <geom name="waypoint241" pos="2.541490598720219 -7.208146559809292 1.01 " size="0.03 0.03 0.03" type="sphere" contype="0" rgba="1 0.9 0 0.7"/>
    <geom name="waypoint242" pos="2.214676661276738 -7.211340044218014 1.01 " size="0.03 0.03 0.03" type="sphere" contype="0" rgba="1 0.9 0 0.7"/>
    <geom name="waypoint243" pos="1.9024717551989008 -7.214040060883201 1.01 " size="0.03 0.03 0.03" type="sphere" contype="0" rgba="1 0.9 0 0.7"/>
    <geom name="waypoint244" pos="1.6079869662377895 -7.216242448511501 1.01 " size="0.03 0.03 0.03" type="sphere" contype="0" rgba="1 0.9 0 0.7"/>
    <geom name="waypoint245" pos="1.3343333801445443 -7.217943045809552 1.01 " size="0.03 0.03 0.03" type="sphere" contype="0" rgba="1 0.9 0 0.7"/>
    <geom name="waypoint246" pos="1.0846220826702515 -7.219137691483995 1.01 " size="0.03 0.03 0.03" type="sphere" contype="0" rgba="1 0.9 0 0.7"/>
    <geom name="waypoint247" pos="0.8619641595660483 -7.219822224241474 1.01 " size="0.03 0.03 0.03" type="sphere" contype="0" rgba="1 0.9 0 0.7"/>
    <geom name="waypoint248" pos="0.669019215804513 -7.219494405145139 1.01 " size="0.03 0.03 0.03" type="sphere" contype="0" rgba="1 0.9 0 0.7"/>
    <geom name="waypoint249" pos="0.4884617461192993 -7.196852196380793 1.01 " size="0.03 0.03 0.03" type="sphere" contype="0" rgba="1 0.9 0 0.7"/>
    <geom name="waypoint250" pos="0.3108153590563982 -7.142844164801192 1.01 " size="0.03 0.03 0.03" type="sphere" contype="0" rgba="1 0.9 0 0.7"/>
    <geom name="waypoint251" pos="0.13706565206677726 -7.060587713602345 1.01 " size="0.03 0.03 0.03" type="sphere" contype="0" rgba="1 0.9 0 0.7"/>
    <geom name="waypoint252" pos="-0.031801777398576814 -6.953200245980285 1.01 " size="0.03 0.03 0.03" type="sphere" contype="0" rgba="1 0.9 0 0.7"/>
    <geom name="waypoint253" pos="-0.1948013318887081 -6.823799165131023 1.01 " size="0.03 0.03 0.03" type="sphere" contype="0" rgba="1 0.9 0 0.7"/>
    <geom name="waypoint254" pos="-0.3509474139526265 -6.67550187425058 1.01 " size="0.03 0.03 0.03" type="sphere" contype="0" rgba="1 0.9 0 0.7"/>
    <geom name="waypoint255" pos="-0.4992544261393754 -6.511425776534974 1.01 " size="0.03 0.03 0.03" type="sphere" contype="0" rgba="1 0.9 0 0.7"/>
    <geom name="waypoint256" pos="-0.6387367709979679 -6.334688275180236 1.01 " size="0.03 0.03 0.03" type="sphere" contype="0" rgba="1 0.9 0 0.7"/>
    <geom name="waypoint257" pos="-0.7684088510774446 -6.148406773382364 1.01 " size="0.03 0.03 0.03" type="sphere" contype="0" rgba="1 0.9 0 0.7"/>
    <geom name="waypoint258" pos="-0.8872850689268205 -5.955698674337401 1.01 " size="0.03 0.03 0.03" type="sphere" contype="0" rgba="1 0.9 0 0.7"/>
    <geom name="waypoint259" pos="-0.9943798270951298 -5.759681381241354 1.01 " size="0.03 0.03 0.03" type="sphere" contype="0" rgba="1 0.9 0 0.7"/>
    <geom name="waypoint260" pos="-1.0887075281314031 -5.563472297290233 1.01 " size="0.03 0.03 0.03" type="sphere" contype="0" rgba="1 0.9 0 0.7"/>
    <geom name="waypoint261" pos="-1.1692825745846605 -5.370188825680081 1.01 " size="0.03 0.03 0.03" type="sphere" contype="0" rgba="1 0.9 0 0.7"/>
    <geom name="waypoint262" pos="-1.235119369003936 -5.1829483696068905 1.01 " size="0.03 0.03 0.03" type="sphere" contype="0" rgba="1 0.9 0 0.7"/>
    <geom name="waypoint263" pos="-1.2852323139382504 -5.004868332266706 1.01 " size="0.03 0.03 0.03" type="sphere" contype="0" rgba="1 0.9 0 0.7"/>
    <geom name="waypoint264" pos="-1.3217103727158672 -4.835410021250941 1.01 " size="0.03 0.03 0.03" type="sphere" contype="0" rgba="1 0.9 0 0.7"/>
    <geom name="waypoint265" pos="-1.3557660508486555 -4.662386972441418 1.01 " size="0.03 0.03 0.03" type="sphere" contype="0" rgba="1 0.9 0 0.7"/>
    <geom name="waypoint266" pos="-1.388407609656445 -4.484760912197539 1.01 " size="0.03 0.03 0.03" type="sphere" contype="0" rgba="1 0.9 0 0.7"/>
    <geom name="waypoint267" pos="-1.4194942347984567 -4.302815620194457 1.01 " size="0.03 0.03 0.03" type="sphere" contype="0" rgba="1 0.9 0 0.7"/>
    <geom name="waypoint268" pos="-1.4488851119339166 -4.116834876107315 1.01 " size="0.03 0.03 0.03" type="sphere" contype="0" rgba="1 0.9 0 0.7"/>
    <geom name="waypoint269" pos="-1.4764394267220495 -3.9271024596112265 1.01 " size="0.03 0.03 0.03" type="sphere" contype="0" rgba="1 0.9 0 0.7"/>
    <geom name="waypoint270" pos="-1.5020163648220775 -3.73390215038136 1.01 " size="0.03 0.03 0.03" type="sphere" contype="0" rgba="1 0.9 0 0.7"/>
    <geom name="waypoint271" pos="-1.525475111893226 -3.537517728092833 1.01 " size="0.03 0.03 0.03" type="sphere" contype="0" rgba="1 0.9 0 0.7"/>
    <geom name="waypoint272" pos="-1.5466748535947172 -3.3382329724208035 1.01 " size="0.03 0.03 0.03" type="sphere" contype="0" rgba="1 0.9 0 0.7"/>
    <geom name="waypoint273" pos="-1.5654747755857776 -3.1363316630403966 1.01 " size="0.03 0.03 0.03" type="sphere" contype="0" rgba="1 0.9 0 0.7"/>
    <geom name="waypoint274" pos="-1.5817340635256283 -2.9320975796267668 1.01 " size="0.03 0.03 0.03" type="sphere" contype="0" rgba="1 0.9 0 0.7"/>
    <geom name="waypoint275" pos="-1.595311903073495 -2.7258145018550333 1.01 " size="0.03 0.03 0.03" type="sphere" contype="0" rgba="1 0.9 0 0.7"/>
    <geom name="waypoint276" pos="-1.6060674798886014 -2.5177662094003583 1.01 " size="0.03 0.03 0.03" type="sphere" contype="0" rgba="1 0.9 0 0.7"/>
    <geom name="waypoint277" pos="-1.6138599796301716 -2.308236481937876 1.01 " size="0.03 0.03 0.03" type="sphere" contype="0" rgba="1 0.9 0 0.7"/>
    <geom name="waypoint278" pos="-1.6185485879574293 -2.0975090991427034 1.01 " size="0.03 0.03 0.03" type="sphere" contype="0" rgba="1 0.9 0 0.7"/>
    <geom name="waypoint279" pos="-1.6199638518740684 -1.8858380868489029 1.01 " size="0.03 0.03 0.03" type="sphere" contype="0" rgba="1 0.9 0 0.7"/>
    <geom name="waypoint280" pos="-1.610991278937474 -1.666348954151081 1.01 " size="0.03 0.03 0.03" type="sphere" contype="0" rgba="1 0.9 0 0.7"/>
    <geom name="waypoint281" pos="-1.587102560417714 -1.4351591446955505 1.01 " size="0.03 0.03 0.03" type="sphere" contype="0" rgba="1 0.9 0 0.7"/>
    <geom name="waypoint282" pos="-1.5495907388438472 -1.194500716076524 1.01 " size="0.03 0.03 0.03" type="sphere" contype="0" rgba="1 0.9 0 0.7"/>
    <geom name="waypoint283" pos="-1.4997488567449384 -0.9466057258882647 1.01 " size="0.03 0.03 0.03" type="sphere" contype="0" rgba="1 0.9 0 0.7"/>
    <geom name="waypoint284" pos="-1.4388699566500482 -0.6937062317249953 1.01 " size="0.03 0.03 0.03" type="sphere" contype="0" rgba="1 0.9 0 0.7"/>
    <geom name="waypoint285" pos="-1.3682470810882332 -0.43803429118094966 1.01 " size="0.03 0.03 0.03" type="sphere" contype="0" rgba="1 0.9 0 0.7"/>
    <geom name="waypoint286" pos="-1.2891732725885616 -0.18182196185038713 1.01 " size="0.03 0.03 0.03" type="sphere" contype="0" rgba="1 0.9 0 0.7"/>
    <geom name="waypoint287" pos="-1.2029415736800873 0.07269869867247891 1.01 " size="0.03 0.03 0.03" type="sphere" contype="0" rgba="1 0.9 0 0.7"/>
    <geom name="waypoint288" pos="-1.11084502689188 0.32329563279338736 1.01 " size="0.03 0.03 0.03" type="sphere" contype="0" rgba="1 0.9 0 0.7"/>
    <geom name="waypoint289" pos="-1.0141766747529912 0.5677367829181232 1.01 " size="0.03 0.03 0.03" type="sphere" contype="0" rgba="1 0.9 0 0.7"/>
    <geom name="waypoint290" pos="-0.9142295597924922 0.8037900914524218 1.01 " size="0.03 0.03 0.03" type="sphere" contype="0" rgba="1 0.9 0 0.7"/>
    <geom name="waypoint291" pos="-0.8122967245394345 1.0292235008020683 1.01 " size="0.03 0.03 0.03" type="sphere" contype="0" rgba="1 0.9 0 0.7"/>
    <geom name="waypoint292" pos="-0.7096712115228887 1.2418049533728048 1.01 " size="0.03 0.03 0.03" type="sphere" contype="0" rgba="1 0.9 0 0.7"/>
    <geom name="waypoint293" pos="-0.6076460632719116 1.4393023915704024 1.01 " size="0.03 0.03 0.03" type="sphere" contype="0" rgba="1 0.9 0 0.7"/>
    <geom name="waypoint294" pos="-0.5075143223155596 1.6194837578006283 1.01 " size="0.03 0.03 0.03" type="sphere" contype="0" rgba="1 0.9 0 0.7"/>
    <geom name="waypoint295" pos="-0.4087136856253761 1.781754023060552 1.01 " size="0.03 0.03 0.03" type="sphere" contype="0" rgba="1 0.9 0 0.7"/>
    <geom name="waypoint296" pos="-0.3018950000598921 1.9342891854561763 1.01 " size="0.03 0.03 0.03" type="sphere" contype="0" rgba="1 0.9 0 0.7"/>
    <geom name="waypoint297" pos="-0.18633994194440184 2.0791895683349764 1.01 " size="0.03 0.03 0.03" type="sphere" contype="0" rgba="1 0.9 0 0.7"/>
    <geom name="waypoint298" pos="-0.06296327242598165 2.217219020534996 1.01 " size="0.03 0.03 0.03" type="sphere" contype="0" rgba="1 0.9 0 0.7"/>
    <geom name="waypoint299" pos="0.0673202473482668 2.3491413908942516 1.01 " size="0.03 0.03 0.03" type="sphere" contype="0" rgba="1 0.9 0 0.7"/>
    <geom name="waypoint300" pos="0.20359585623126766 2.475720528250788 1.01 " size="0.03 0.03 0.03" type="sphere" contype="0" rgba="1 0.9 0 0.7"/>
    <geom name="waypoint301" pos="0.3449487930759223 2.5977202814426246 1.01 " size="0.03 0.03 0.03" type="sphere" contype="0" rgba="1 0.9 0 0.7"/>
    <geom name="waypoint302" pos="0.4904642967351469 2.7159044993078054 1.01 " size="0.03 0.03 0.03" type="sphere" contype="0" rgba="1 0.9 0 0.7"/>
    <geom name="waypoint303" pos="0.6392276060618616 2.83103703068436 1.01 " size="0.03 0.03 0.03" type="sphere" contype="0" rgba="1 0.9 0 0.7"/>
    <geom name="waypoint304" pos="0.7903239599089628 2.943881724410312 1.01 " size="0.03 0.03 0.03" type="sphere" contype="0" rgba="1 0.9 0 0.7"/>
    <geom name="waypoint305" pos="0.942838597129378 3.055202429323705 1.01 " size="0.03 0.03 0.03" type="sphere" contype="0" rgba="1 0.9 0 0.7"/>
    <geom name="waypoint306" pos="1.095856756576004 3.1657629942625594 1.01 " size="0.03 0.03 0.03" type="sphere" contype="0" rgba="1 0.9 0 0.7"/>
    <geom name="waypoint307" pos="1.2484636771017665 3.276327268064916 1.01 " size="0.03 0.03 0.03" type="sphere" contype="0" rgba="1 0.9 0 0.7"/>
    <geom name="waypoint308" pos="1.3997445975595646 3.387659099568801 1.01 " size="0.03 0.03 0.03" type="sphere" contype="0" rgba="1 0.9 0 0.7"/>
    <geom name="waypoint309" pos="1.5487847568023243 3.500522337612251 1.01 " size="0.03 0.03 0.03" type="sphere" contype="0" rgba="1 0.9 0 0.7"/>
    <geom name="waypoint310" pos="1.6946693936829424 3.6156808310332895 1.01 " size="0.03 0.03 0.03" type="sphere" contype="0" rgba="1 0.9 0 0.7"/>
    <geom name="waypoint311" pos="1.8379640955122127 3.735050664065255 1.01 " size="0.03 0.03 0.03" type="sphere" contype="0" rgba="1 0.9 0 0.7"/>
    <geom name="waypoint312" pos="1.9803014600770783 3.859364851721251 1.01 " size="0.03 0.03 0.03" type="sphere" contype="0" rgba="1 0.9 0 0.7"/>
    <geom name="waypoint313" pos="2.1220720587226785 3.987268547202627 1.01 " size="0.03 0.03 0.03" type="sphere" contype="0" rgba="1 0.9 0 0.7"/>
    <geom name="waypoint314" pos="2.2636645709269967 4.117404714335999 1.01 " size="0.03 0.03 0.03" type="sphere" contype="0" rgba="1 0.9 0 0.7"/>
    <geom name="waypoint315" pos="2.4054676761679894 4.248416316947928 1.01 " size="0.03 0.03 0.03" type="sphere" contype="0" rgba="1 0.9 0 0.7"/>
    <geom name="waypoint316" pos="2.54787005392364 4.378946318865029 1.01 " size="0.03 0.03 0.03" type="sphere" contype="0" rgba="1 0.9 0 0.7"/>
    <geom name="waypoint317" pos="2.6912603836719073 4.507637683913879 1.01 " size="0.03 0.03 0.03" type="sphere" contype="0" rgba="1 0.9 0 0.7"/>
    <geom name="waypoint318" pos="2.8360273448907742 4.633133375921078 1.01 " size="0.03 0.03 0.03" type="sphere" contype="0" rgba="1 0.9 0 0.7"/>
    <geom name="waypoint319" pos="2.9825596170581963 4.754076358713204 1.01 " size="0.03 0.03 0.03" type="sphere" contype="0" rgba="1 0.9 0 0.7"/>
    <geom name="waypoint320" pos="3.1312458796521496 4.869109596116861 1.01 " size="0.03 0.03 0.03" type="sphere" contype="0" rgba="1 0.9 0 0.7"/>
    <geom name="waypoint321" pos="3.2824748121506153 4.976876051958636 1.01 " size="0.03 0.03 0.03" type="sphere" contype="0" rgba="1 0.9 0 0.7"/>
    <geom name="waypoint322" pos="3.4366350940315447 5.076018690065119 1.01 " size="0.03 0.03 0.03" type="sphere" contype="0" rgba="1 0.9 0 0.7"/>
    <geom name="waypoint323" pos="3.5941154047729276 5.1651804742629 1.01 " size="0.03 0.03 0.03" type="sphere" contype="0" rgba="1 0.9 0 0.7"/>
    <geom name="waypoint324" pos="3.7553044238527136 5.243004368378568 1.01 " size="0.03 0.03 0.03" type="sphere" contype="0" rgba="1 0.9 0 0.7"/>
    <geom name="waypoint325" pos="3.9205908307488926 5.308133336238719 1.01 " size="0.03 0.03 0.03" type="sphere" contype="0" rgba="1 0.9 0 0.7"/>
    <geom name="waypoint326" pos="4.090230959782615 5.360416114549611 1.01 " size="0.03 0.03 0.03" type="sphere" contype="0" rgba="1 0.9 0 0.7"/>
    <geom name="waypoint327" pos="4.26334744580355 5.409435765077998 1.01 " size="0.03 0.03 0.03" type="sphere" contype="0" rgba="1 0.9 0 0.7"/>
    <geom name="waypoint328" pos="4.4397625978253465 5.4573072345047615 1.01 " size="0.03 0.03 0.03" type="sphere" contype="0" rgba="1 0.9 0 0.7"/>
    <geom name="waypoint329" pos="4.619552193753082 5.503732604408988 1.01 " size="0.03 0.03 0.03" type="sphere" contype="0" rgba="1 0.9 0 0.7"/>
    <geom name="waypoint330" pos="4.802792011491847 5.54841395636977 1.01 " size="0.03 0.03 0.03" type="sphere" contype="0" rgba="1 0.9 0 0.7"/>
    <geom name="waypoint331" pos="4.989557828946694 5.5910533719661855 1.01 " size="0.03 0.03 0.03" type="sphere" contype="0" rgba="1 0.9 0 0.7"/>
    <geom name="waypoint332" pos="5.179925424022715 5.631352932777318 1.01 " size="0.03 0.03 0.03" type="sphere" contype="0" rgba="1 0.9 0 0.7"/>
    <geom name="waypoint333" pos="5.373970574624972 5.669014720382254 1.01 " size="0.03 0.03 0.03" type="sphere" contype="0" rgba="1 0.9 0 0.7"/>
    <geom name="waypoint334" pos="5.571769058658552 5.703740816360085 1.01 " size="0.03 0.03 0.03" type="sphere" contype="0" rgba="1 0.9 0 0.7"/>
    <geom name="waypoint335" pos="5.773396654028518 5.735233302289885 1.01 " size="0.03 0.03 0.03" type="sphere" contype="0" rgba="1 0.9 0 0.7"/>
    <geom name="waypoint336" pos="5.978929138639956 5.76319425975074 1.01 " size="0.03 0.03 0.03" type="sphere" contype="0" rgba="1 0.9 0 0.7"/>
    <geom name="waypoint337" pos="6.188442290397927 5.787325770321744 1.01 " size="0.03 0.03 0.03" type="sphere" contype="0" rgba="1 0.9 0 0.7"/>
    <geom name="waypoint338" pos="6.402011887207516 5.80732991558197 1.01 " size="0.03 0.03 0.03" type="sphere" contype="0" rgba="1 0.9 0 0.7"/>
    <geom name="waypoint339" pos="6.619713706973808 5.822908777110508 1.01 " size="0.03 0.03 0.03" type="sphere" contype="0" rgba="1 0.9 0 0.7"/>
    <geom name="waypoint340" pos="6.841623527601853 5.833764436486443 1.01 " size="0.03 0.03 0.03" type="sphere" contype="0" rgba="1 0.9 0 0.7"/>
    <geom name="waypoint341" pos="7.067817126996748 5.839598975288862 1.01 " size="0.03 0.03 0.03" type="sphere" contype="0" rgba="1 0.9 0 0.7"/>
    <geom name="waypoint342" pos="7.303249342812272 5.842073127514862 1.01 " size="0.03 0.03 0.03" type="sphere" contype="0" rgba="1 0.9 0 0.7"/>
    <geom name="waypoint343" pos="7.554728512067142 5.844353658337108 1.01 " size="0.03 0.03 0.03" type="sphere" contype="0" rgba="1 0.9 0 0.7"/>
    <geom name="waypoint344" pos="7.819911314284363 5.846489685316531 1.01 " size="0.03 0.03 0.03" type="sphere" contype="0" rgba="1 0.9 0 0.7"/>
    <geom name="waypoint345" pos="8.09631508644261 5.848478754357039 1.01 " size="0.03 0.03 0.03" type="sphere" contype="0" rgba="1 0.9 0 0.7"/>
    <geom name="waypoint346" pos="8.381457165520512 5.850318411362558 1.01 " size="0.03 0.03 0.03" type="sphere" contype="0" rgba="1 0.9 0 0.7"/>
    <geom name="waypoint347" pos="8.672854888496738 5.852006202236995 1.01 " size="0.03 0.03 0.03" type="sphere" contype="0" rgba="1 0.9 0 0.7"/>
    <geom name="waypoint348" pos="8.968025592349953 5.853539672884278 1.01 " size="0.03 0.03 0.03" type="sphere" contype="0" rgba="1 0.9 0 0.7"/>
    <geom name="waypoint349" pos="9.264486614058793 5.854916369208315 1.01 " size="0.03 0.03 0.03" type="sphere" contype="0" rgba="1 0.9 0 0.7"/>
    <geom name="waypoint350" pos="9.55975529060194 5.856133837113025 1.01 " size="0.03 0.03 0.03" type="sphere" contype="0" rgba="1 0.9 0 0.7"/>
    <geom name="waypoint351" pos="9.851348958958015 5.857189622502324 1.01 " size="0.03 0.03 0.03" type="sphere" contype="0" rgba="1 0.9 0 0.7"/>
    <geom name="waypoint352" pos="10.136784956105704 5.858081271280136 1.01 " size="0.03 0.03 0.03" type="sphere" contype="0" rgba="1 0.9 0 0.7"/>
    <geom name="waypoint353" pos="10.413580619023634 5.858806329350361 1.01 " size="0.03 0.03 0.03" type="sphere" contype="0" rgba="1 0.9 0 0.7"/>
    <geom name="waypoint354" pos="10.679253284690484 5.859362342616937 1.01 " size="0.03 0.03 0.03" type="sphere" contype="0" rgba="1 0.9 0 0.7"/>
    <geom name="waypoint355" pos="10.931320290084889 5.859746856983765 1.01 " size="0.03 0.03 0.03" type="sphere" contype="0" rgba="1 0.9 0 0.7"/>
    <geom name="waypoint356" pos="11.167298972185522 5.859957418354768 1.01 " size="0.03 0.03 0.03" type="sphere" contype="0" rgba="1 0.9 0 0.7"/>
    <geom name="waypoint357" pos="11.385586696538617 5.857543823512273 1.01 " size="0.03 0.03 0.03" type="sphere" contype="0" rgba="1 0.9 0 0.7"/>
    <geom name="waypoint358" pos="11.597523558682573 5.816901230814149 1.01 " size="0.03 0.03 0.03" type="sphere" contype="0" rgba="1 0.9 0 0.7"/>
    <geom name="waypoint359" pos="11.806853401005768 5.729896021244709 1.01 " size="0.03 0.03 0.03" type="sphere" contype="0" rgba="1 0.9 0 0.7"/>
    <geom name="waypoint360" pos="12.013005869343907 5.601192609335993 1.01 " size="0.03 0.03 0.03" type="sphere" contype="0" rgba="1 0.9 0 0.7"/>
    <geom name="waypoint361" pos="12.21541060953272 5.435455409620044 1.01 " size="0.03 0.03 0.03" type="sphere" contype="0" rgba="1 0.9 0 0.7"/>
    <geom name="waypoint362" pos="12.413497267407898 5.2373488366289145 1.01 " size="0.03 0.03 0.03" type="sphere" contype="0" rgba="1 0.9 0 0.7"/>
    <geom name="waypoint363" pos="12.606695488805176 5.011537304894636 1.01 " size="0.03 0.03 0.03" type="sphere" contype="0" rgba="1 0.9 0 0.7"/>
    <geom name="waypoint364" pos="12.794434919560253 4.76268522894927 1.01 " size="0.03 0.03 0.03" type="sphere" contype="0" rgba="1 0.9 0 0.7"/>
    <geom name="waypoint365" pos="12.976145205508852 4.4954570233248505 1.01 " size="0.03 0.03 0.03" type="sphere" contype="0" rgba="1 0.9 0 0.7"/>
    <geom name="waypoint366" pos="13.151255992486686 4.214517102553405 1.01 " size="0.03 0.03 0.03" type="sphere" contype="0" rgba="1 0.9 0 0.7"/>
    <geom name="waypoint367" pos="13.319196926329468 3.924529881167009 1.01 " size="0.03 0.03 0.03" type="sphere" contype="0" rgba="1 0.9 0 0.7"/>
    <geom name="waypoint368" pos="13.479397652872912 3.630159773697676 1.01 " size="0.03 0.03 0.03" type="sphere" contype="0" rgba="1 0.9 0 0.7"/>
    <geom name="waypoint369" pos="13.631287817952726 3.336071194677478 1.01 " size="0.03 0.03 0.03" type="sphere" contype="0" rgba="1 0.9 0 0.7"/>
    <geom name="waypoint370" pos="13.774297067404637 3.046928558638438 1.01 " size="0.03 0.03 0.03" type="sphere" contype="0" rgba="1 0.9 0 0.7"/>
    <geom name="waypoint371" pos="13.907855047064345 2.7673962801126155 1.01 " size="0.03 0.03 0.03" type="sphere" contype="0" rgba="1 0.9 0 0.7"/>
    <geom name="waypoint372" pos="14.031391402767575 2.5021387736320366 1.01 " size="0.03 0.03 0.03" type="sphere" contype="0" rgba="1 0.9 0 0.7"/>
    <geom name="waypoint373" pos="14.147549590373801 2.245870296771906 1.01 " size="0.03 0.03 0.03" type="sphere" contype="0" rgba="1 0.9 0 0.7"/>
    <geom name="waypoint374" pos="14.263325451481725 1.9778360768854832 1.01 " size="0.03 0.03 0.03" type="sphere" contype="0" rgba="1 0.9 0 0.7"/>
    <geom name="waypoint375" pos="14.378209296924894 1.6986698796390467 1.01 " size="0.03 0.03 0.03" type="sphere" contype="0" rgba="1 0.9 0 0.7"/>
    <geom name="waypoint376" pos="14.491352270366333 1.4100168984027237 1.01 " size="0.03 0.03 0.03" type="sphere" contype="0" rgba="1 0.9 0 0.7"/>
    <geom name="waypoint377" pos="14.601905515469108 1.113522326546571 1.01 " size="0.03 0.03 0.03" type="sphere" contype="0" rgba="1 0.9 0 0.7"/>
    <geom name="waypoint378" pos="14.709020175896256 0.8108313574407191 1.01 " size="0.03 0.03 0.03" type="sphere" contype="0" rgba="1 0.9 0 0.7"/>
    <geom name="waypoint379" pos="14.81184739531083 0.5035891844552262 1.01 " size="0.03 0.03 0.03" type="sphere" contype="0" rgba="1 0.9 0 0.7"/>
    <geom name="waypoint380" pos="14.909538317375866 0.19344100096021852 1.01 " size="0.03 0.03 0.03" type="sphere" contype="0" rgba="1 0.9 0 0.7"/>
    <geom name="waypoint381" pos="15.001244085754426 -0.11796799967424047 1.01 " size="0.03 0.03 0.03" type="sphere" contype="0" rgba="1 0.9 0 0.7"/>
    <geom name="waypoint382" pos="15.086115844109546 -0.42899262407803274 1.01 " size="0.03 0.03 0.03" type="sphere" contype="0" rgba="1 0.9 0 0.7"/>
    <geom name="waypoint383" pos="15.163304736104275 -0.7379876788810726 1.01 " size="0.03 0.03 0.03" type="sphere" contype="0" rgba="1 0.9 0 0.7"/>
    <geom name="waypoint384" pos="15.231961905401667 -1.043307970713288 1.01 " size="0.03 0.03 0.03" type="sphere" contype="0" rgba="1 0.9 0 0.7"/>
    <geom name="waypoint385" pos="15.291238495664764 -1.343308306204552 1.01 " size="0.03 0.03 0.03" type="sphere" contype="0" rgba="1 0.9 0 0.7"/>
    <geom name="waypoint386" pos="15.340285650556615 -1.6363434919848012 1.01 " size="0.03 0.03 0.03" type="sphere" contype="0" rgba="1 0.9 0 0.7"/>
    <geom name="waypoint387" pos="15.378254513740263 -1.9207683346839153 1.01 " size="0.03 0.03 0.03" type="sphere" contype="0" rgba="1 0.9 0 0.7"/>
    <geom name="waypoint388" pos="15.404499660110243 -2.195326208366696 1.01 " size="0.03 0.03 0.03" type="sphere" contype="0" rgba="1 0.9 0 0.7"/>
    <geom name="waypoint389" pos="15.42494720937616 -2.470716369738053 1.01 " size="0.03 0.03 0.03" type="sphere" contype="0" rgba="1 0.9 0 0.7"/>
    <geom name="waypoint390" pos="15.442901263750473 -2.7510180226562286 1.01 " size="0.03 0.03 0.03" type="sphere" contype="0" rgba="1 0.9 0 0.7"/>
    <geom name="waypoint391" pos="15.458680702269225 -3.034347469812517 1.01 " size="0.03 0.03 0.03" type="sphere" contype="0" rgba="1 0.9 0 0.7"/>
    <geom name="waypoint392" pos="15.472604403968454 -3.3188210138982512 1.01 " size="0.03 0.03 0.03" type="sphere" contype="0" rgba="1 0.9 0 0.7"/>
    <geom name="waypoint393" pos="15.484991247884201 -3.6025549576047595 1.01 " size="0.03 0.03 0.03" type="sphere" contype="0" rgba="1 0.9 0 0.7"/>
    <geom name="waypoint394" pos="15.49616011305251 -3.883665603623333 1.01 " size="0.03 0.03 0.03" type="sphere" contype="0" rgba="1 0.9 0 0.7"/>
    <geom name="waypoint395" pos="15.506429878509405 -4.160269254645312 1.01 " size="0.03 0.03 0.03" type="sphere" contype="0" rgba="1 0.9 0 0.7"/>
    <geom name="waypoint396" pos="15.516119423290935 -4.430482213361991 1.01 " size="0.03 0.03 0.03" type="sphere" contype="0" rgba="1 0.9 0 0.7"/>
    <geom name="waypoint397" pos="15.52554762643314 -4.6924207824647075 1.01 " size="0.03 0.03 0.03" type="sphere" contype="0" rgba="1 0.9 0 0.7"/>
    <geom name="waypoint398" pos="15.535033366972058 -4.944201264644763 1.01 " size="0.03 0.03 0.03" type="sphere" contype="0" rgba="1 0.9 0 0.7"/>
    <geom name="waypoint399" pos="15.544895523943724 -5.1839399625934925 1.01 " size="0.03 0.03 0.03" type="sphere" contype="0" rgba="1 0.9 0 0.7"/>
    <geom name="waypoint400" pos="15.555452976384185 -5.409753179002188 1.01 " size="0.03 0.03 0.03" type="sphere" contype="0" rgba="1 0.9 0 0.7"/>
    <geom name="waypoint401" pos="15.567024603329479 -5.619757216562182 1.01 " size="0.03 0.03 0.03" type="sphere" contype="0" rgba="1 0.9 0 0.7"/>
    <geom name="waypoint402" pos="15.579929283815636 -5.8120683779647955 1.01 " size="0.03 0.03 0.03" type="sphere" contype="0" rgba="1 0.9 0 0.7"/>
    <geom name="waypoint403" pos="15.594485896878702 -5.984802965901332 1.01 " size="0.03 0.03 0.03" type="sphere" contype="0" rgba="1 0.9 0 0.7"/>
    <geom name="waypoint404" pos="15.61074171508135 -6.140388392187537 1.01 " size="0.03 0.03 0.03" type="sphere" contype="0" rgba="1 0.9 0 0.7"/>
    <geom name="waypoint405" pos="15.627928102654224 -6.292248519519861 1.01 " size="0.03 0.03 0.03" type="sphere" contype="0" rgba="1 0.9 0 0.7"/>
    <geom name="waypoint406" pos="15.645945660309284 -6.44092859433766 1.01 " size="0.03 0.03 0.03" type="sphere" contype="0" rgba="1 0.9 0 0.7"/>
    <geom name="waypoint407" pos="15.664765438801984 -6.5857688302982025 1.01 " size="0.03 0.03 0.03" type="sphere" contype="0" rgba="1 0.9 0 0.7"/>
    <geom name="waypoint408" pos="15.684358488887801 -6.726109441058781 1.01 " size="0.03 0.03 0.03" type="sphere" contype="0" rgba="1 0.9 0 0.7"/>
    <geom name="waypoint409" pos="15.704695861322186 -6.86129064027667 1.01 " size="0.03 0.03 0.03" type="sphere" contype="0" rgba="1 0.9 0 0.7"/>
    <geom name="waypoint410" pos="15.725748606860598 -6.990652641609153 1.01 " size="0.03 0.03 0.03" type="sphere" contype="0" rgba="1 0.9 0 0.7"/>
    <geom name="waypoint411" pos="15.747487776258515 -7.11353565871352 1.01 " size="0.03 0.03 0.03" type="sphere" contype="0" rgba="1 0.9 0 0.7"/>
    <geom name="waypoint412" pos="15.769884420271392 -7.229279905247038 1.01 " size="0.03 0.03 0.03" type="sphere" contype="0" rgba="1 0.9 0 0.7"/>
    <geom name="waypoint413" pos="15.792909589654688 -7.337225594867 1.01 " size="0.03 0.03 0.03" type="sphere" contype="0" rgba="1 0.9 0 0.7"/>
    <geom name="waypoint414" pos="15.816534335163869 -7.436712941230676 1.01 " size="0.03 0.03 0.03" type="sphere" contype="0" rgba="1 0.9 0 0.7"/>
    <geom name="waypoint415" pos="15.840729707554397 -7.52708215799536 1.01 " size="0.03 0.03 0.03" type="sphere" contype="0" rgba="1 0.9 0 0.7"/>
    <geom name="waypoint416" pos="15.865466757581732 -7.607673458818325 1.01 " size="0.03 0.03 0.03" type="sphere" contype="0" rgba="1 0.9 0 0.7"/>
    <geom name="waypoint417" pos="15.89071653600134 -7.677827057356853 1.01 " size="0.03 0.03 0.03" type="sphere" contype="0" rgba="1 0.9 0 0.7"/>
    <geom name="waypoint418" pos="15.916450093568685 -7.73688316726823 1.01 " size="0.03 0.03 0.03" type="sphere" contype="0" rgba="1 0.9 0 0.7"/>
  </worldbody>
  <equality>
    <connect body1="left-plantar-rod" body2="left-foot" anchor="0.35012 0 0"/>
    <connect body1="left-achilles-rod" body2="left-heel-spring" anchor="0.5012 0 0"/>
    <connect body1="right-plantar-rod" body2="right-foot" anchor="0.35012 0 0"/>
    <connect body1="right-achilles-rod" body2="right-heel-spring" anchor="0.5012 0 0"/>
  </equality>
  <actuator>
    <!-- User parameter is the maximum no-load motor RPM -->
    <motor name="left-hip-roll" joint="left-hip-roll" gear="25" ctrllimited="true" ctrlrange="-4.5 4.5" user="2900"/>
    <motor name="left-hip-yaw" joint="left-hip-yaw" gear="25" ctrllimited="true" ctrlrange="-4.5 4.5" user="2900"/>
    <motor name="left-hip-pitch" joint="left-hip-pitch" gear="16" ctrllimited="true" ctrlrange="-12.2 12.2" user="1300"/>
    <motor name="left-knee" joint="left-knee" gear="16" ctrllimited="true" ctrlrange="-12.2 12.2" user="1300"/>
    <motor name="left-foot" joint="left-foot" gear="50" ctrllimited="true" ctrlrange="-0.9 0.9" user="5500"/>
    <motor name="right-hip-roll" joint="right-hip-roll" gear="25" ctrllimited="true" ctrlrange="-4.5 4.5" user="2900"/>
    <motor name="right-hip-yaw" joint="right-hip-yaw" gear="25" ctrllimited="true" ctrlrange="-4.5 4.5" user="2900"/>
    <motor name="right-hip-pitch" joint="right-hip-pitch" gear="16" ctrllimited="true" ctrlrange="-12.2 12.2" user="1300"/>
    <motor name="right-knee" joint="right-knee" gear="16" ctrllimited="true" ctrlrange="-12.2 12.2" user="1300"/>
    <motor name="right-foot" joint="right-foot" gear="50" ctrllimited="true" ctrlrange="-0.9 0.9" user="5500"/>
  </actuator>
  <sensor>
    <!-- User parameter is the number of absolute encoder bits -->
    <actuatorpos name="left-hip-roll-input" actuator="left-hip-roll" user="13"/>
    <actuatorpos name="left-hip-yaw-input" actuator="left-hip-yaw" user="13"/>
    <actuatorpos name="left-hip-pitch-input" actuator="left-hip-pitch" user="13"/>
    <actuatorpos name="left-knee-input" actuator="left-knee" user="13"/>
    <actuatorpos name="left-foot-input" actuator="left-foot" user="18"/>
    <jointpos name="left-shin-output" joint="left-shin" user="18" noise="2e-4"/>
    <jointpos name="left-tarsus-output" joint="left-tarsus" user="18" noise="2e-4"/>
    <jointpos name="left-foot-output" joint="left-foot" user="13"/>
    <actuatorpos name="right-hip-roll-input" actuator="right-hip-roll" user="13"/>
    <actuatorpos name="right-hip-yaw-input" actuator="right-hip-yaw" user="13"/>
    <actuatorpos name="right-hip-pitch-input" actuator="right-hip-pitch" user="13"/>
    <actuatorpos name="right-knee-input" actuator="right-knee" user="13"/>
    <actuatorpos name="right-foot-input" actuator="right-foot" user="18"/>
    <jointpos name="right-shin-output" joint="right-shin" user="18" noise="2e-4"/>
    <jointpos name="right-tarsus-output" joint="right-tarsus" user="18" noise="2e-4"/>
    <jointpos name="right-foot-output" joint="right-foot" user="13"/>
    <framequat name="pelvis-orientation" objtype="site" objname="imu"/>
    <gyro name="pelvis-angular-velocity" site="imu" noise="5e-4" cutoff="34.9"/>
    <accelerometer name="pelvis-linear-acceleration" site="imu" noise="1e-2" cutoff="157"/>
    <magnetometer name="pelvis-magnetometer" site="imu"/>
  </sensor>
</mujoco>
